Workbook

Sheet OCT-2026
H2: 46296 | I2: 46300 | J2: 46301 | K2: 46302 | L2: 46303 | M2: 46304 | N2: 46307 | O2: 46308 | P2: 46309 | Q2: 46310 | R2: 46311 | S2: 46314 | T2: 46316 | U2: 46317 | V2: 46318 | W2: 46321 | X2: 46322 | Z2: OCT | AA2: OCT ROI
A3: CODE | B3: NAME | C3: ID | D3: STRATEGY | E3: SEGMENT | F3: FUND | H3: THU | I3: MON | J3: TUE | K3: WED | L3: THU | M3: FRI | N3: MON | O3: TUE | P3: WED | Q3: THU | R3: FRI | S3: MON | T3: WED | U3: THU | V3: FRI | W3: MON | X3: TUE | AH3: OPT | AI3: 13780
A4: P3389 | B4: Abdul | C4: XTS09 | D4: ATR-Strangle | E4: NSEFO | F4: 0.5 | H4: -10416 | I4: 3572 | J4: 22112 | K4: 29052 | L4: 42300 | M4: 0 | N4: 20138 | O4: 2032 | P4: -4915 | Q4: 20376 | R4: -3015 | S4: -4789 | T4: 9292 | U4: -3426 | V4: 7452 | W4: -6562 | X4: -11883 | Z4: =SUM(H4:Y4) -> 111320 | AA4: =IFERROR(Z4/F4*100,0)/10000000 -> 2.2264 | AH4: FUTURE EXP | AI4: 2865
A5: P3379 | B5: DK SIR_A | C5: XTS01,ATS1530 | D5: 20_60 | E5: NSEFO | F5: 3 | H5: -37424 | I5: -168374 | J5: 205000 | K5: 94938 | L5: 96755 | M5: 117145 | N5: 267650 | O5: -166064 | P5: 20733 | Q5: -56438 | R5: 95575 | S5: 57336 | T5: 60100 | U5: -254059 | V5: 106000 | W5: -57900 | X5: -95500 | Z5: =SUM(H5:Y5) -> 285473 | AA5: =IFERROR(Z5/F5*100,0)/10000000 -> 0.95157667
A6: P3459 | B6: DK SIR_A | C6: ATS1532 | D6: new strategy_48 | E6: NSEFO | F6: 1 | H6: 61880 | I6: -64153 | J6: -20800 | K6: 50440 | L6: 44170 | M6: 56800 | N6: -10500 | O6: 68700 | P6: 47900 | Q6: 13400 | R6: 68940 | S6: 93200 | T6: 119900 | U6: -47135 | V6: -61600 | W6: -169055 | X6: 76500 | Z6: =SUM(H6:Y6) -> 328587 | AA6: =IFERROR(Z6/F6*100,0)/10000000 -> 3.28587
A7: P3166 | B7: Aman Dohre | C7: XTS03 | D7: MACD/Direction | E7: STOCK OP | F7: 3 | H7: -136000 | I7: 118000 | J7: -49000 | K7: -140210 | L7: -117400 | M7: 124400 | N7: -116400 | O7: 190500 | P7: 114600 | Q7: 6628 | R7: -95555 | S7: 71500 | T7: -11104 | U7: -22819 | V7: -37900 | W7: 92400 | X7: 121200 | Z7: =SUM(H7:Y7) -> 112840 | AA7: =IFERROR(Z7/F7*100,0)/10000000 -> 0.37613333 | AD7: -17173
A8: P3390 | B8: Aman Dohre | C8: XTS34 | D8: NSE FO | E8: NSEFO | F8: 1.5 | H8: 19390 | I8: 50890 | J8: 19770 | K8: 18290 | L8: 11000 | M8: 31390 | N8: 27600 | O8: 18375 | P8: -2657 | Q8: 70564 | R8: 36368 | S8: -78711 | T8: 84000 | U8: -33919 | V8: 0 | W8: -16364 | X8: 10700 | Z8: =SUM(H8:Y8) -> 266686 | AA8: =IFERROR(Z8/F8*100,0)/10000000 -> 1.7779067 | AC8: 244627
A9: P3390_1 | B9: Aman Dohre | C9: ATS1507 | D9: NSE FO | F9: 0.6 | H9: 14700 | I9: 31300 | J9: -8734 | K9: 4948 | L9: 25000 | M9: 11000 | N9: -22490 | O9: 34300 | P9: -22700 | Q9: 29000 | R9: 10900 | S9: 60900 | T9: 99900 | U9: -105197 | V9: 0 | W9: 50600 | X9: 62800 | Z9: =SUM(H9:Y9) -> 276227 | AA9: =IFERROR(Z9/F9*100,0)/10000000 -> 4.6037833 | AC9: 229732 | AD9: =(AC9+AC8)/10000000*13780 -> 653.6667
A10: P3117 | B10: Ansh Aggarwal | C10: ATS_1007 | D10: Falcon | E10: NSEFO | F10: 15 | H10: 35250 | I10: -205500 | J10: 0 | K10: 13730 | L10: 0 | M10: 4400 | N10: -66300 | O10: 316800 | P10: 0 | Q10: -235700 | R10: 1160 | S10: 47501 | T10: 1280 | U10: 0 | V10: 0 | W10: 0 | X10: 0 | Z10: =SUM(H10:Y10) -> -87379 | AA10: =IFERROR(Z10/F10*100,0)/10000000 -> -0.058252667
A11: P3323_1 | B11: Amit&Kartik | C11: XTS35 | D11: Strangle/Spread | E11: NSEFO | F11: 6 | H11: 0 | I11: 331 | J11: 170100 | K11: 0 | L11: 55700 | M11: 0 | N11: 16000 | O11: 266734 | P11: 0 | Q11: 102848 | R11: 32041 | S11: -270400 | T11: 0 | U11: 0 | V11: 0 | W11: 12420 | X11: -114575 | Z11: =SUM(H11:Y11) -> 271199 | AA11: =IFERROR(Z11/F11*100,0)/10000000 -> 0.45199833
A12: P2827 | B12: Bharat | C12: UT | D12: ETF | E12: CASH | F12: 1 | H12: -1852 | I12: 1200 | J12: 330 | K12: -1616 | L12: -2953 | M12: 3600 | N12: -1450 | O12: 1122 | P12: -2961 | Q12: -100 | R12: 2072 | S12: -1965 | T12: -3031 | U12: -2466 | V12: -3576 | W12: 1111 | X12: -413 | Z12: =SUM(H12:Y12) -> -12948 | AA12: =IFERROR(Z12/F12*100,0)/10000000 -> -0.12948
A13: P3090 | B13: Bharat | C13: XTS04 | D13: STRADDLE | E13: NSEFO | F13: 2.5 | H13: 28670 | I13: -2070 | J13: 41753 | K13: 0 | L13: 22700 | M13: 25100 | N13: 19400 | O13: 33540 | P13: -4729 | Q13: -9088 | R13: -39105 | S13: -15290 | T13: 30473 | U13: -8452 | V13: 24090 | W13: -40457 | X13: -15543 | Z13: =SUM(H13:Y13) -> 90992 | AA13: =IFERROR(Z13/F13*100,0)/10000000 -> 0.363968
A14: P2954 | B14: Yogesh | C14: XTS39 | D14: STRADDLE | E14: NSEFO | F14: 2.2 | H14: 34712 | I14: -291 | J14: 43482 | K14: 0 | L14: 30900 | M14: 22730 | N14: 14168 | O14: 37416 | P14: 2460 | Q14: -9798 | R14: -48238 | S14: -9374 | T14: 27044 | U14: 0 | V14: 31125 | W14: -37218 | X14: -17800 | Z14: =SUM(H14:Y14) -> 121318 | AA14: =IFERROR(Z14/F14*100,0)/10000000 -> 0.55144545 | AD14: =AD7-AD9 -> -17826.667 | AG14: -13200 | AI14: =AG14+AD14 -> -31026.667
A15: P3079 | B15: Yogesh | C15: UT | D15: ETF | E15: CASH | F15: 1 | H15: -10000 | I15: 10800 | J15: 19700 | K15: -6218 | L15: -30200 | M15: 20000 | N15: -2965 | O15: 17000 | P15: -1624 | Q15: -6519 | R15: 14300 | S15: -13384 | T15: -19818 | U15: -12160 | V15: -27445 | W15: 17900 | X15: 17130 | Z15: =SUM(H15:Y15) -> -13503 | AA15: =IFERROR(Z15/F15*100,0)/10000000 -> -0.13503
A16: P2817 | B16: DK Sir_M | C16: S1504 | D16: Maximum | E16: NSEFO | F16: 2.5 | H16: 0 | I16: -38551 | J16: 0 | K16: 0 | L16: 0 | M16: -43080 | N16: 49165 | O16: 42400 | P16: -41370 | Q16: 45200 | R16: 62711 | S16: 230600 | T16: 289570 | U16: -248047 | V16: 50000 | W16: 30270 | X16: 157200 | Z16: =SUM(H16:Y16) -> 586068 | AA16: =IFERROR(Z16/F16*100,0)/10000000 -> 2.344272 | AI16: 4000000 | AJ16: =AI16*7/100 -> 280000 | AL16: =15*12 -> 180
A17: P2792 | B17: DK Sir_T | C17: S1502 | D17: ThanosNF | E17: NSEFO | F17: 4 | H17: 0 | I17: -34123 | J17: 0 | K17: 0 | L17: 0 | M17: 34600 | N17: 25724 | O17: 70400 | P17: -85300 | Q17: 38300 | R17: 33838 | S17: 157000 | T17: 259384 | U17: -340399 | V17: 410000 | W17: 168000 | X17: -171000 | Z17: =SUM(H17:Y17) -> 566424 | AA17: =IFERROR(Z17/F17*100,0)/10000000 -> 1.41606 | AJ17: =AJ16/12 -> 23333.333
A18: P3311 | B18: Himansu Pal | C18: ATS_1510 | D18: Directional | E18: NSEFO | F18: 1.5 | H18: 81300 | I18: -101486 | J18: 65000 | K18: -95099 | L18: 141000 | M18: 136800 | N18: 86900 | O18: 29900 | P18: -50000 | Q18: 156158 | R18: 31800 | S18: 17210 | T18: 109500 | U18: -42447 | V18: 113500 | W18: 39300 | X18: 32700 | Z18: =SUM(H18:Y18) -> 752036 | AA18: =IFERROR(Z18/F18*100,0)/10000000 -> 5.0135733
A19: P3181 | B19: Harshit | C19: XTS32 | D19: SELF | E19: NSEFO | F19: 1.1 | H19: -67291 | I19: -83397 | J19: 0 | K19: 0 | L19: 0 | M19: 0 | N19: 0 | O19: 0 | P19: 0 | Q19: 0 | R19: 0 | S19: 0 | T19: 0 | U19: 0 | V19: 0 | W19: 0 | X19: 0 | Z19: =SUM(H19:Y19) -> -150688 | AA19: =IFERROR(Z19/F19*100,0)/10000000 -> -1.3698909 | AE19: 54000
A20: P3400 | B20: Aman sharma | C20: XTS37 | D20: SELF | E20: NSEFO | F20: 0.25 | H20: -26528 | I20: -45096 | J20: -3830 | K20: 7212 | L20: -17400 | M20: -10893 | N20: -5900 | O20: -5537 | P20: 0 | Q20: 0 | R20: 0 | S20: 0 | T20: 0 | U20: -3000 | V20: 0 | W20: 0 | X20: 140 | Z20: =SUM(H20:Y20) -> -110832 | AA20: =IFERROR(Z20/F20*100,0)/10000000 -> -4.43328 | AE20: 11100
A21: P3091 | B21: Hardik | C21: XTS010 | D21: SELF | E21: NSEFO | F21: 2 | H21: 0 | I21: 0 | J21: 0 | K21: 0 | L21: 0 | M21: 0 | N21: 0 | O21: 0 | P21: 0 | Q21: 0 | R21: 0 | S21: 0 | T21: 0 | U21: 0 | V21: 0 | W21: 0 | Z21: =SUM(H21:Y21) -> 0 | AA21: =IFERROR(Z21/F21*100,0)/10000000 -> 0 | AE21: 0
A22: P3408 | B22: Hardik | C22: XTS20 | D22: SELF | E22: NSEFO | F22: 0.25 | H22: 0 | I22: 0 | J22: 0 | K22: 0 | L22: 0 | M22: 0 | N22: 0 | O22: 0 | P22: 0 | Q22: 0 | R22: 0 | S22: 0 | T22: 0 | U22: 0 | V22: 0 | W22: 0 | X22: 0 | Z22: =SUM(H22:Y22) -> 0 | AA22: =IFERROR(Z22/F22*100,0)/10000000 -> 0 | AE22: =SUM(AE19:AE21) -> 65100
A23: P3109 | B23: Jyoti Prakesh | C23: XTS30 | D23: Straddle | E23: NSEFO | F23: 1.1 | H23: -20520 | I23: -29845 | J23: 39988 | K23: 38700 | L23: -1623 | M23: 561 | N23: -32723 | O23: -7059 | P23: 28800 | Q23: -13000 | R23: 12772 | S23: -40307 | T23: -21044 | U23: -30404 | V23: -200 | W23: 54387 | X23: -5748 | Z23: =SUM(H23:Y23) -> -27265 | AA23: =IFERROR(Z23/F23*100,0)/10000000 -> -0.24786364
A24: P3146 | B24: Jinesh Jain | C24: CQS5 | D24: CASH | E24: CASH | F24: 2.3 | H24: -164650 | I24: 85700 | J24: 145750 | K24: -128600 | L24: -381800 | M24: 239700 | N24: -28900 | O24: 226700 | P24: 14473 | Q24: -30980 | R24: 18400 | S24: -154667 | T24: -213001 | U24: -102504 | V24: -303200 | W24: 77900 | X24: 133200 | Z24: =SUM(H24:Y24) -> -566479 | AA24: =IFERROR(Z24/F24*100,0)/10000000 -> -2.4629522
A25: P3244 | B25: Jinesh Jain | C25: XTS41 | D25: Stock fo | F25: 0.2 | N25: -300 | O25: 58100 | P25: 10600 | Q25: -13826 | R25: -10395 | S25: -4185 | T25: 15180 | U25: -12503 | V25: -13000 | W25: 71400 | X25: 87920 | Z25: =SUM(H25:Y25) -> 188991 | AA25: =IFERROR(Z25/F25*100,0)/10000000 -> 9.44955
A26: P3434 | B26: Kapil Kumar | C26: ATS_1529 | E26: NSEFO | F26: 0.5 | H26: 12250 | I26: 3476 | J26: -13000 | K26: -2835 | L26: 10900 | M26: -200 | N26: 6366 | O26: 4942 | P26: -7150 | Q26: 1600 | R26: -19506 | S26: -11119 | T26: 462 | U26: -9552 | V26: -4293 | W26: -18145 | X26: 14000 | Z26: =SUM(H26:Y26) -> -31804 | AA26: =IFERROR(Z26/F26*100,0)/10000000 -> -0.63608
A27: P2105 | B27: Kamlesh | C27: S1501 | D27: Wanda | E27: NSEFO | F27: 5 | H27: 0 | I27: -116700 | J27: 1100 | K27: 0 | L27: 0 | M27: -25000 | N27: 65100 | O27: 45700 | P27: -133000 | Q27: 130000 | R27: 140100 | S27: 103000 | T27: 926000 | U27: 66500 | V27: 691000 | W27: 397000 | X27: -482000 | Z27: =SUM(H27:Y27) -> 1808800 | AA27: =IFERROR(Z27/F27*100,0)/10000000 -> 3.6176
A28: P3024 | B28: Kartaram | C28: ATS_1005 | D28: Spider 2.0 | E28: NSEFO | F28: 10 | H28: 98800 | I28: 0 | J28: 11535 | K28: 302380 | L28: 55800 | M28: 16200 | N28: -40416 | O28: 137300 | P28: 583300 | Q28: 11260 | R28: 40700 | S28: -648400 | T28: -178800 | U28: -1068 | V28: 0 | W28: -162700 | X28: 0 | Z28: =SUM(H28:Y28) -> 225891 | AA28: =IFERROR(Z28/F28*100,0)/10000000 -> 0.225891
A29: P3446 | B29: Gargi Bharti | C29: ATS_1511 | E29: NSEFO | F29: 0.5 | I29: 3624 | J29: 14752 | K29: -6445 | L29: 7920 | M29: 6919 | N29: 20700 | O29: -10961 | P29: -11200 | Q29: 18300 | R29: 30700 | S29: -27300 | T29: 37000 | U29: -45489 | V29: -13700 | W29: -28900 | X29: 32266 | Z29: =SUM(H29:Y29) -> 28186 | AA29: =IFERROR(Z29/F29*100,0)/10000000 -> 0.56372
A30: P3202 | B30: Gagandeep | C30: XTS12 | D30: SELF | E30: NSEFO | F30: 5 | H30: 90508 | I30: 0 | J30: 310622 | K30: 0 | L30: 155700 | M30: 0 | N30: 0 | O30: 226901 | P30: 0 | Q30: -161746 | R30: 0 | S30: 219189 | T30: 0 | U30: 0 | V30: 0 | W30: 0 | X30: 0 | Z30: =SUM(H30:Y30) -> 841174 | AA30: =IFERROR(Z30/F30*100,0)/10000000 -> 1.682348
A31: P3020 | B31: Mahavir Jindal | C31: XTS02 | D31: SELF | E31: NSEFO | F31: 5 | H31: 115180 | I31: -225930 | J31: 0 | K31: 2600 | L31: 44000 | M31: 39485 | N31: 19560 | O31: 38370 | P31: 10450 | Q31: 59316 | R31: 37102 | S31: 0 | T31: 0 | U31: 0 | V31: 0 | W31: 0 | X31: 0 | Z31: =SUM(H31:Y31) -> 140133 | AA31: =IFERROR(Z31/F31*100,0)/10000000 -> 0.280266
A32: P3341 | B32: Maneesh Yadav | C32: XTS18 | D32: Theta Dominance | E32: NSEFO | F32: 0.5 | H32: -51008 | I32: 13880 | J32: 48621 | K32: -7694 | L32: 34100 | M32: 19000 | N32: 20700 | O32: 12614 | P32: 7400 | Q32: 19095 | R32: 22950 | S32: -78603 | T32: 99571 | U32: -52226 | V32: -43208 | W32: 4974 | X32: -27000 | Z32: =SUM(H32:Y32) -> 43166 | AA32: =IFERROR(Z32/F32*100,0)/10000000 -> 0.86332
A33: P2971_2 | B33: Neeraj Garg | C33: S1514 | D33: ACE1 | E33: NSEFO | F33: 0.4 | H33: 9270 | I33: 28255 | J33: 42650 | K33: 1293 | L33: 33700 | M33: 17495 | N33: 35813 | O33: 26000 | P33: -45331 | Q33: 21700 | R33: 30400 | S33: 39761 | T33: 34200 | U33: -6364 | V33: 33000 | W33: 38495 | X33: 3700 | Z33: =SUM(H33:Y33) -> 344037 | AA33: =IFERROR(Z33/F33*100,0)/10000000 -> 8.600925
A34: P3070 | B34: Prateek | C34: ATS_1504 | D34: Smart Strangle | E34: NSEFO | F34: 4 | H34: -91628 | I34: -39194 | J34: 81490 | K34: -98197 | L34: 149600 | M34: 77460 | N34: 85200 | O34: -20461 | P34: -170280 | Q34: 243315 | R34: -53800 | S34: 50100 | T34: 139300 | U34: -42000 | V34: 44000 | W34: 16600 | X34: -60500 | Z34: =SUM(H34:Y34) -> 311005 | AA34: =IFERROR(Z34/F34*100,0)/10000000 -> 0.7775125 | AD34: 46634
A35: P2999 | B35: Prateek | C35: ATS_1519 | D35: ETF | E35: ETF | F35: 1 | H35: -49178 | I35: 20700 | J35: 51300 | K35: -13148 | L35: -107400 | M35: 56914 | N35: 10400 | O35: 51221 | P35: -5394 | Q35: -35576 | R35: 26400 | S35: -56804 | T35: 69566 | U35: -45990 | V35: -111976 | W35: 41600 | X35: 60600 | Z35: =SUM(H35:Y35) -> -36765 | AA35: =IFERROR(Z35/F35*100,0)/10000000 -> -0.36765
A36: P3000 | B36: Prateek | C36: XTS19 | D36: NSEFO | E36: NSEFO | H36: 0 | I36: 0 | J36: 0 | K36: 0 | L36: 0 | M36: 0 | N36: 0 | O36: 0 | P36: 0 | Q36: 0 | R36: 0 | S36: 0 | T36: 0 | U36: 0 | V36: 0 | W36: 0 | X36: 0 | Z36: =SUM(H36:Y36) -> 0 | AA36: =IFERROR(Z36/F36*100,0)/10000000 -> 0 | AC36: 233083 | AD36: =(AC37+AC36)/10000000*13780 -> 706.6384
A37: P3186 | B37: Prateek | C37: XTS17 | D37: Opton | E37: NSEFO | F37: 0.5 | H37: 3712 | I37: -16258 | J37: 19175 | K37: -15524 | L37: 23400 | M37: 0 | N37: 15668 | O37: 5849 | P37: -37180 | Q37: -26608 | R37: 192 | S37: -5600 | T37: 12700 | U37: -1126 | V37: 3835 | W37: -6562 | X37: -17725 | Z37: =SUM(H37:Y37) -> -42052 | AA37: =IFERROR(Z37/F37*100,0)/10000000 -> -0.84104 | AC37: 279717
A38: P3135 | B38: Piyush Singhal | C38: ATS_1509 | D38: Directional strangle | E38: NSEFO | F38: 3 | H38: 158900 | I38: -331500 | J38: 276700 | K38: 79524 | L38: -8546 | M38: -110144 | N38: 341200 | O38: -109461 | P38: 59000 | Q38: 303000 | R38: -11174 | S38: 223000 | T38: 496500 | U38: -376400 | V38: -42428 | W38: -219600 | X38: -306450 | Z38: =SUM(H38:Y38) -> 422121 | AA38: =IFERROR(Z38/F38*100,0)/10000000 -> 1.40707 | AD38: =+AD34-AD36 -> 45927.362
A39: P3152 | B39: Rashil Khetan | C39: XTS29 | E39: NSEFO | F39: 0.1 | H39: 18070 | I39: 15000 | J39: -7417 | K39: -19285 | L39: 59000 | M39: 19459 | N39: -17325 | O39: 62950 | P39: -33154 | Q39: -64866 | R39: -72104 | S39: 32900 | T39: -13561 | U39: -68770 | V39: 1089 | W39: 15022 | X39: -118577 | Z39: =SUM(H39:Y39) -> -191569 | AA39: =IFERROR(Z39/F39*100,0)/10000000 -> -19.1569
A40: P3342 | B40: Raghav Tuli | C40: ATS1526 | D40: Flaxi trade | E40: NSEFO | F40: 0.5 | H40: 0 | I40: 7600 | J40: 12200 | K40: -16500 | L40: 26900 | M40: 12000 | N40: 0 | O40: -11341 | P40: -18160 | Q40: 12680 | R40: 1932 | S40: 0 | T40: 28200 | U40: -3870 | V40: 16400 | W40: 12700 | X40: -5383 | Z40: =SUM(H40:Y40) -> 75358 | AA40: =IFERROR(Z40/F40*100,0)/10000000 -> 1.50716
A41: P3082 | B41: Ramakar Jha | C41: ATS_1503 | D41: CASH | E41: CASH | F41: 1 | H41: -219160 | I41: -41680 | J41: 174856 | K41: -85245 | L41: -484000 | M41: -52500 | N41: 107800 | O41: -65513 | P41: 139726 | Q41: -435700 | R41: 60000 | S41: -71974 | T41: 3429 | U41: -106396 | V41: -6386 | W41: 119000 | X41: 216130 | Z41: =SUM(H41:Y41) -> -747613 | AA41: =IFERROR(Z41/F41*100,0)/10000000 -> -7.47613
...

Sheet FY-(26-27)Q3
G2: OCT | H2: OCT ROI | I2: NOV | J2: NOV ROI | K2: DEC | L2: DEC ROI | M2: Q 3 | N2: ROI Q3
A3: CODE | B3: NAME | C3: ID | D3: STRATEGY | E3: SEGMENT | F3: FUND(CR)
A4: P3389 | B4: Abdul | C4: XTS09 | D4: ATR-Strangle | E4: NSEFO | F4: 0.5 | G4: =IFERROR(VLOOKUP($A$3:$A$116,'OCT-2026'!$A$4:$ADI$120,MATCH('FY-(26-27)Q3'!$G$2:$H$2,'OCT-2026'!$A$2:$DJ$2,0),0),0) -> 111320 | H4: =IFERROR(VLOOKUP($A$3:$A$116,'OCT-2026'!$A$4:$ADI$120,MATCH('FY-(26-27)Q3'!$G$2:$H$2,'OCT-2026'!$A$2:$DJ$2,0),0),0) -> 2.2264 | I4: =IFERROR(VLOOKUP($A$3:$A$116,'[1]NOV-2026'!$A$4:$ADL$124,MATCH('FY-(26-27)Q3'!$I$2:$J$2,'[1]NOV-2026'!$A$2:$DM$2,0),0),0) -> 0 | J4: =IFERROR(VLOOKUP($A$3:$A$116,'[1]NOV-2026'!$A$4:$ADL$124,MATCH('FY-(26-27)Q3'!$I$2:$J$2,'[1]NOV-2026'!$A$2:$DM$2,0),0),0) -> 0 | K4: =IFERROR(VLOOKUP($A$3:$A$116,'[2]DEC-2026'!$A$4:$AEE$125,MATCH('FY-(26-27)Q3'!$K$2:$L$2,'[2]DEC-2026'!$A$2:$EF$2,0),0),0) -> 0 | L4: =IFERROR(VLOOKUP($A$3:$A$116,'[2]DEC-2026'!$A$4:$AEE$125,MATCH('FY-(26-27)Q3'!$K$2:$L$2,'[2]DEC-2026'!$A$2:$EF$2,0),0),0) -> 0 | M4: =G4+I4+K4 -> 111320 | N4: =H4+J4+L4 -> 2.2264
A5: P3379 | B5: DK SIR_A | C5: XTS01,ATS1530 | D5: 20_60 | E5: NSEFO | F5: 3.5 | G5: =IFERROR(VLOOKUP($A$3:$A$116,'OCT-2026'!$A$4:$ADI$120,MATCH('FY-(26-27)Q3'!$G$2:$H$2,'OCT-2026'!$A$2:$DJ$2,0),0),0) -> 285473 | H5: =IFERROR(VLOOKUP($A$3:$A$116,'OCT-2026'!$A$4:$ADI$120,MATCH('FY-(26-27)Q3'!$G$2:$H$2,'OCT-2026'!$A$2:$DJ$2,0),0),0) -> 0.95157667 | I5: =IFERROR(VLOOKUP($A$3:$A$116,'[1]NOV-2026'!$A$4:$ADL$124,MATCH('FY-(26-27)Q3'!$I$2:$J$2,'[1]NOV-2026'!$A$2:$DM$2,0),0),0) -> 0 | J5: =IFERROR(VLOOKUP($A$3:$A$116,'[1]NOV-2026'!$A$4:$ADL$124,MATCH('FY-(26-27)Q3'!$I$2:$J$2,'[1]NOV-2026'!$A$2:$DM$2,0),0),0) -> 0 | K5: =IFERROR(VLOOKUP($A$3:$A$116,'[2]DEC-2026'!$A$4:$AEE$125,MATCH('FY-(26-27)Q3'!$K$2:$L$2,'[2]DEC-2026'!$A$2:$EF$2,0),0),0) -> 0 | L5: =IFERROR(VLOOKUP($A$3:$A$116,'[2]DEC-2026'!$A$4:$AEE$125,MATCH('FY-(26-27)Q3'!$K$2:$L$2,'[2]DEC-2026'!$A$2:$EF$2,0),0),0) -> 0 | M5: =G5+I5+K5 -> 285473 | N5: =H5+J5+L5 -> 0.95157667
A6: P3459 | B6: DK SIR_A | C6: ATS1532 | D6: new strategy_48 | E6: NSEFO | F6: 1 | G6: =IFERROR(VLOOKUP($A$3:$A$116,'OCT-2026'!$A$4:$ADI$120,MATCH('FY-(26-27)Q3'!$G$2:$H$2,'OCT-2026'!$A$2:$DJ$2,0),0),0) -> 328587 | H6: =IFERROR(VLOOKUP($A$3:$A$116,'OCT-2026'!$A$4:$ADI$120,MATCH('FY-(26-27)Q3'!$G$2:$H$2,'OCT-2026'!$A$2:$DJ$2,0),0),0) -> 3.28587 | I6: =IFERROR(VLOOKUP($A$3:$A$116,'[1]NOV-2026'!$A$4:$ADL$124,MATCH('FY-(26-27)Q3'!$I$2:$J$2,'[1]NOV-2026'!$A$2:$DM$2,0),0),0) -> 0 | J6: =IFERROR(VLOOKUP($A$3:$A$116,'[1]NOV-2026'!$A$4:$ADL$124,MATCH('FY-(26-27)Q3'!$I$2:$J$2,'[1]NOV-2026'!$A$2:$DM$2,0),0),0) -> 0 | K6: =IFERROR(VLOOKUP($A$3:$A$116,'[2]DEC-2026'!$A$4:$AEE$125,MATCH('FY-(26-27)Q3'!$K$2:$L$2,'[2]DEC-2026'!$A$2:$EF$2,0),0),0) -> 0 | L6: =IFERROR(VLOOKUP($A$3:$A$116,'[2]DEC-2026'!$A$4:$AEE$125,MATCH('FY-(26-27)Q3'!$K$2:$L$2,'[2]DEC-2026'!$A$2:$EF$2,0),0),0) -> 0 | M6: =G6+I6+K6 -> 328587 | N6: =H6+J6+L6 -> 3.28587
A7: P3166 | B7: Aman Dohre | C7: XTS03 | D7: MACD/Direction | E7: NSEFO | F7: 3 | G7: =IFERROR(VLOOKUP($A$3:$A$116,'OCT-2026'!$A$4:$ADI$120,MATCH('FY-(26-27)Q3'!$G$2:$H$2,'OCT-2026'!$A$2:$DJ$2,0),0),0) -> 112840 | H7: =IFERROR(VLOOKUP($A$3:$A$116,'OCT-2026'!$A$4:$ADI$120,MATCH('FY-(26-27)Q3'!$G$2:$H$2,'OCT-2026'!$A$2:$DJ$2,0),0),0) -> 0.37613333 | I7: =IFERROR(VLOOKUP($A$3:$A$116,'[1]NOV-2026'!$A$4:$ADL$124,MATCH('FY-(26-27)Q3'!$I$2:$J$2,'[1]NOV-2026'!$A$2:$DM$2,0),0),0) -> 0 | J7: =IFERROR(VLOOKUP($A$3:$A$116,'[1]NOV-2026'!$A$4:$ADL$124,MATCH('FY-(26-27)Q3'!$I$2:$J$2,'[1]NOV-2026'!$A$2:$DM$2,0),0),0) -> 0 | K7: =IFERROR(VLOOKUP($A$3:$A$116,'[2]DEC-2026'!$A$4:$AEE$125,MATCH('FY-(26-27)Q3'!$K$2:$L$2,'[2]DEC-2026'!$A$2:$EF$2,0),0),0) -> 0 | L7: =IFERROR(VLOOKUP($A$3:$A$116,'[2]DEC-2026'!$A$4:$AEE$125,MATCH('FY-(26-27)Q3'!$K$2:$L$2,'[2]DEC-2026'!$A$2:$EF$2,0),0),0) -> 0 | M7: =G7+I7+K7 -> 112840 | N7: =H7+J7+L7 -> 0.37613333
A8: P3390 | B8: Aman Dohre | C8: XTS34 | D8: NSE FO | E8: NSEFO | F8: 1.5 | G8: =IFERROR(VLOOKUP($A$3:$A$116,'OCT-2026'!$A$4:$ADI$120,MATCH('FY-(26-27)Q3'!$G$2:$H$2,'OCT-2026'!$A$2:$DJ$2,0),0),0) -> 266686 | H8: =IFERROR(VLOOKUP($A$3:$A$116,'OCT-2026'!$A$4:$ADI$120,MATCH('FY-(26-27)Q3'!$G$2:$H$2,'OCT-2026'!$A$2:$DJ$2,0),0),0) -> 1.7779067 | I8: =IFERROR(VLOOKUP($A$3:$A$116,'[1]NOV-2026'!$A$4:$ADL$124,MATCH('FY-(26-27)Q3'!$I$2:$J$2,'[1]NOV-2026'!$A$2:$DM$2,0),0),0) -> 0 | J8: =IFERROR(VLOOKUP($A$3:$A$116,'[1]NOV-2026'!$A$4:$ADL$124,MATCH('FY-(26-27)Q3'!$I$2:$J$2,'[1]NOV-2026'!$A$2:$DM$2,0),0),0) -> 0 | K8: =IFERROR(VLOOKUP($A$3:$A$116,'[2]DEC-2026'!$A$4:$AEE$125,MATCH('FY-(26-27)Q3'!$K$2:$L$2,'[2]DEC-2026'!$A$2:$EF$2,0),0),0) -> 0 | L8: =IFERROR(VLOOKUP($A$3:$A$116,'[2]DEC-2026'!$A$4:$AEE$125,MATCH('FY-(26-27)Q3'!$K$2:$L$2,'[2]DEC-2026'!$A$2:$EF$2,0),0),0) -> 0 | M8: =G8+I8+K8 -> 266686 | N8: =H8+J8+L8 -> 1.7779067
A9: P3390_1 | B9: Aman Dohre | C9: ATS1507 | D9: NSE FO | E9: NSEFO | F9: 0.6 | G9: =IFERROR(VLOOKUP($A$3:$A$116,'OCT-2026'!$A$4:$ADI$120,MATCH('FY-(26-27)Q3'!$G$2:$H$2,'OCT-2026'!$A$2:$DJ$2,0),0),0) -> 276227 | H9: =IFERROR(VLOOKUP($A$3:$A$116,'OCT-2026'!$A$4:$ADI$120,MATCH('FY-(26-27)Q3'!$G$2:$H$2,'OCT-2026'!$A$2:$DJ$2,0),0),0) -> 4.6037833 | I9: =IFERROR(VLOOKUP($A$3:$A$116,'[1]NOV-2026'!$A$4:$ADL$124,MATCH('FY-(26-27)Q3'!$I$2:$J$2,'[1]NOV-2026'!$A$2:$DM$2,0),0),0) -> 0 | J9: =IFERROR(VLOOKUP($A$3:$A$116,'[1]NOV-2026'!$A$4:$ADL$124,MATCH('FY-(26-27)Q3'!$I$2:$J$2,'[1]NOV-2026'!$A$2:$DM$2,0),0),0) -> 0 | K9: =IFERROR(VLOOKUP($A$3:$A$116,'[2]DEC-2026'!$A$4:$AEE$125,MATCH('FY-(26-27)Q3'!$K$2:$L$2,'[2]DEC-2026'!$A$2:$EF$2,0),0),0) -> 0 | L9: =IFERROR(VLOOKUP($A$3:$A$116,'[2]DEC-2026'!$A$4:$AEE$125,MATCH('FY-(26-27)Q3'!$K$2:$L$2,'[2]DEC-2026'!$A$2:$EF$2,0),0),0) -> 0 | M9: =G9+I9+K9 -> 276227 | N9: =H9+J9+L9 -> 4.6037833
A10: P3117 | B10: Ansh Aggarwal | C10: ATS_1007 | D10: Falcon | E10: NSEFO | F10: 15 | G10: =IFERROR(VLOOKUP($A$3:$A$116,'OCT-2026'!$A$4:$ADI$120,MATCH('FY-(26-27)Q3'!$G$2:$H$2,'OCT-2026'!$A$2:$DJ$2,0),0),0) -> -87379 | H10: =IFERROR(VLOOKUP($A$3:$A$116,'OCT-2026'!$A$4:$ADI$120,MATCH('FY-(26-27)Q3'!$G$2:$H$2,'OCT-2026'!$A$2:$DJ$2,0),0),0) -> -0.058252667 | I10: =IFERROR(VLOOKUP($A$3:$A$116,'[1]NOV-2026'!$A$4:$ADL$124,MATCH('FY-(26-27)Q3'!$I$2:$J$2,'[1]NOV-2026'!$A$2:$DM$2,0),0),0) -> 0 | J10: =IFERROR(VLOOKUP($A$3:$A$116,'[1]NOV-2026'!$A$4:$ADL$124,MATCH('FY-(26-27)Q3'!$I$2:$J$2,'[1]NOV-2026'!$A$2:$DM$2,0),0),0) -> 0 | K10: =IFERROR(VLOOKUP($A$3:$A$116,'[2]DEC-2026'!$A$4:$AEE$125,MATCH('FY-(26-27)Q3'!$K$2:$L$2,'[2]DEC-2026'!$A$2:$EF$2,0),0),0) -> 0 | L10: =IFERROR(VLOOKUP($A$3:$A$116,'[2]DEC-2026'!$A$4:$AEE$125,MATCH('FY-(26-27)Q3'!$K$2:$L$2,'[2]DEC-2026'!$A$2:$EF$2,0),0),0) -> 0 | M10: =G10+I10+K10 -> -87379 | N10: =H10+J10+L10 -> -0.058252667
A11: P3323_1 | B11: Amit&Kartik | C11: XTS35 | D11: Strangle/Spread | E11: NSEFO | F11: 6 | G11: =IFERROR(VLOOKUP($A$3:$A$116,'OCT-2026'!$A$4:$ADI$120,MATCH('FY-(26-27)Q3'!$G$2:$H$2,'OCT-2026'!$A$2:$DJ$2,0),0),0) -> 271199 | H11: =IFERROR(VLOOKUP($A$3:$A$116,'OCT-2026'!$A$4:$ADI$120,MATCH('FY-(26-27)Q3'!$G$2:$H$2,'OCT-2026'!$A$2:$DJ$2,0),0),0) -> 0.45199833 | I11: =IFERROR(VLOOKUP($A$3:$A$116,'[1]NOV-2026'!$A$4:$ADL$124,MATCH('FY-(26-27)Q3'!$I$2:$J$2,'[1]NOV-2026'!$A$2:$DM$2,0),0),0) -> 0 | J11: =IFERROR(VLOOKUP($A$3:$A$116,'[1]NOV-2026'!$A$4:$ADL$124,MATCH('FY-(26-27)Q3'!$I$2:$J$2,'[1]NOV-2026'!$A$2:$DM$2,0),0),0) -> 0 | K11: =IFERROR(VLOOKUP($A$3:$A$116,'[2]DEC-2026'!$A$4:$AEE$125,MATCH('FY-(26-27)Q3'!$K$2:$L$2,'[2]DEC-2026'!$A$2:$EF$2,0),0),0) -> 0 | L11: =IFERROR(VLOOKUP($A$3:$A$116,'[2]DEC-2026'!$A$4:$AEE$125,MATCH('FY-(26-27)Q3'!$K$2:$L$2,'[2]DEC-2026'!$A$2:$EF$2,0),0),0) -> 0 | M11: =G11+I11+K11 -> 271199 | N11: =H11+J11+L11 -> 0.45199833
A12: P2827 | B12: Bharat | C12: UT | D12: CASH | E12: CASH | F12: 1 | G12: =IFERROR(VLOOKUP($A$3:$A$116,'OCT-2026'!$A$4:$ADI$120,MATCH('FY-(26-27)Q3'!$G$2:$H$2,'OCT-2026'!$A$2:$DJ$2,0),0),0) -> -12948 | H12: =IFERROR(VLOOKUP($A$3:$A$116,'OCT-2026'!$A$4:$ADI$120,MATCH('FY-(26-27)Q3'!$G$2:$H$2,'OCT-2026'!$A$2:$DJ$2,0),0),0) -> -0.12948 | I12: =IFERROR(VLOOKUP($A$3:$A$116,'[1]NOV-2026'!$A$4:$ADL$124,MATCH('FY-(26-27)Q3'!$I$2:$J$2,'[1]NOV-2026'!$A$2:$DM$2,0),0),0) -> 0 | J12: =IFERROR(VLOOKUP($A$3:$A$116,'[1]NOV-2026'!$A$4:$ADL$124,MATCH('FY-(26-27)Q3'!$I$2:$J$2,'[1]NOV-2026'!$A$2:$DM$2,0),0),0) -> 0 | K12: =IFERROR(VLOOKUP($A$3:$A$116,'[2]DEC-2026'!$A$4:$AEE$125,MATCH('FY-(26-27)Q3'!$K$2:$L$2,'[2]DEC-2026'!$A$2:$EF$2,0),0),0) -> 0 | L12: =IFERROR(VLOOKUP($A$3:$A$116,'[2]DEC-2026'!$A$4:$AEE$125,MATCH('FY-(26-27)Q3'!$K$2:$L$2,'[2]DEC-2026'!$A$2:$EF$2,0),0),0) -> 0 | M12: =G12+I12+K12 -> -12948 | N12: =H12+J12+L12 -> -0.12948
A13: P3090 | B13: Bharat | C13: XTS04 | D13: STRADDLE | E13: NSEFO | F13: 1 | G13: =IFERROR(VLOOKUP($A$3:$A$116,'OCT-2026'!$A$4:$ADI$120,MATCH('FY-(26-27)Q3'!$G$2:$H$2,'OCT-2026'!$A$2:$DJ$2,0),0),0) -> 90992 | H13: =IFERROR(VLOOKUP($A$3:$A$116,'OCT-2026'!$A$4:$ADI$120,MATCH('FY-(26-27)Q3'!$G$2:$H$2,'OCT-2026'!$A$2:$DJ$2,0),0),0) -> 0.363968 | I13: =IFERROR(VLOOKUP($A$3:$A$116,'[1]NOV-2026'!$A$4:$ADL$124,MATCH('FY-(26-27)Q3'!$I$2:$J$2,'[1]NOV-2026'!$A$2:$DM$2,0),0),0) -> 0 | J13: =IFERROR(VLOOKUP($A$3:$A$116,'[1]NOV-2026'!$A$4:$ADL$124,MATCH('FY-(26-27)Q3'!$I$2:$J$2,'[1]NOV-2026'!$A$2:$DM$2,0),0),0) -> 0 | K13: =IFERROR(VLOOKUP($A$3:$A$116,'[2]DEC-2026'!$A$4:$AEE$125,MATCH('FY-(26-27)Q3'!$K$2:$L$2,'[2]DEC-2026'!$A$2:$EF$2,0),0),0) -> 0 | L13: =IFERROR(VLOOKUP($A$3:$A$116,'[2]DEC-2026'!$A$4:$AEE$125,MATCH('FY-(26-27)Q3'!$K$2:$L$2,'[2]DEC-2026'!$A$2:$EF$2,0),0),0) -> 0 | M13: =G13+I13+K13 -> 90992 | N13: =H13+J13+L13 -> 0.363968
A14: P3079 | B14: Yogesh | C14: UT | D14: CASH | E14: CASH | F14: 1 | G14: =IFERROR(VLOOKUP($A$3:$A$116,'OCT-2026'!$A$4:$ADI$120,MATCH('FY-(26-27)Q3'!$G$2:$H$2,'OCT-2026'!$A$2:$DJ$2,0),0),0) -> -13503 | H14: =IFERROR(VLOOKUP($A$3:$A$116,'OCT-2026'!$A$4:$ADI$120,MATCH('FY-(26-27)Q3'!$G$2:$H$2,'OCT-2026'!$A$2:$DJ$2,0),0),0) -> -0.13503 | I14: =IFERROR(VLOOKUP($A$3:$A$116,'[1]NOV-2026'!$A$4:$ADL$124,MATCH('FY-(26-27)Q3'!$I$2:$J$2,'[1]NOV-2026'!$A$2:$DM$2,0),0),0) -> 0 | J14: =IFERROR(VLOOKUP($A$3:$A$116,'[1]NOV-2026'!$A$4:$ADL$124,MATCH('FY-(26-27)Q3'!$I$2:$J$2,'[1]NOV-2026'!$A$2:$DM$2,0),0),0) -> 0 | K14: =IFERROR(VLOOKUP($A$3:$A$116,'[2]DEC-2026'!$A$4:$AEE$125,MATCH('FY-(26-27)Q3'!$K$2:$L$2,'[2]DEC-2026'!$A$2:$EF$2,0),0),0) -> 0 | L14: =IFERROR(VLOOKUP($A$3:$A$116,'[2]DEC-2026'!$A$4:$AEE$125,MATCH('FY-(26-27)Q3'!$K$2:$L$2,'[2]DEC-2026'!$A$2:$EF$2,0),0),0) -> 0 | M14: =G14+I14+K14 -> -13503 | N14: =H14+J14+L14 -> -0.13503
A15: P2954 | B15: Yogesh kumar | C15: XTS39 | D15: STRADDLE | E15: NSEFO | F15: 0.2 | G15: =IFERROR(VLOOKUP($A$3:$A$116,'OCT-2026'!$A$4:$ADI$120,MATCH('FY-(26-27)Q3'!$G$2:$H$2,'OCT-2026'!$A$2:$DJ$2,0),0),0) -> 121318 | H15: =IFERROR(VLOOKUP($A$3:$A$116,'OCT-2026'!$A$4:$ADI$120,MATCH('FY-(26-27)Q3'!$G$2:$H$2,'OCT-2026'!$A$2:$DJ$2,0),0),0) -> 0.55144545 | I15: =IFERROR(VLOOKUP($A$3:$A$116,'[1]NOV-2026'!$A$4:$ADL$124,MATCH('FY-(26-27)Q3'!$I$2:$J$2,'[1]NOV-2026'!$A$2:$DM$2,0),0),0) -> 0 | J15: =IFERROR(VLOOKUP($A$3:$A$116,'[1]NOV-2026'!$A$4:$ADL$124,MATCH('FY-(26-27)Q3'!$I$2:$J$2,'[1]NOV-2026'!$A$2:$DM$2,0),0),0) -> 0 | K15: =IFERROR(VLOOKUP($A$3:$A$116,'[2]DEC-2026'!$A$4:$AEE$125,MATCH('FY-(26-27)Q3'!$K$2:$L$2,'[2]DEC-2026'!$A$2:$EF$2,0),0),0) -> 0 | L15: =IFERROR(VLOOKUP($A$3:$A$116,'[2]DEC-2026'!$A$4:$AEE$125,MATCH('FY-(26-27)Q3'!$K$2:$L$2,'[2]DEC-2026'!$A$2:$EF$2,0),0),0) -> 0 | M15: =G15+I15+K15 -> 121318 | N15: =H15+J15+L15 -> 0.55144545
... A23: P3146 | B23: Jinesh Jain | C23: CQS5 | D23: CASH | E23: CASH | F23: 2.3 | G23: =IFERROR(VLOOKUP($A$3:$A$116,'OCT-2026'!$A$4:$ADI$120,MATCH('FY-(26-27)Q3'!$G$2:$H$2,'OCT-2026'!$A$2:$DJ$2,0),0),0) -> -566479 | H23: =IFERROR(VLOOKUP($A$3:$A$116,'OCT-2026'!$A$4:$ADI$120,MATCH('FY-(26-27)Q3'!$G$2:$H$2,'OCT-2026'!$A$2:$DJ$2,0),0),0) -> -2.4629522 | I23: =IFERROR(VLOOKUP($A$3:$A$116,'[1]NOV-2026'!$A$4:$ADL$124,MATCH('FY-(26-27)Q3'!$I$2:$J$2,'[1]NOV-2026'!$A$2:$DM$2,0),0),0) -> 0 | J23: =IFERROR(VLOOKUP($A$3:$A$116,'[1]NOV-2026'!$A$4:$ADL$124,MATCH('FY-(26-27)Q3'!$I$2:$J$2,'[1]NOV-2026'!$A$2:$DM$2,0),0),0) -> 0 | K23: =IFERROR(VLOOKUP($A$3:$A$116,'[2]DEC-2026'!$A$4:$AEE$125,MATCH('FY-(26-27)Q3'!$K$2:$L$2,'[2]DEC-2026'!$A$2:$EF$2,0),0),0) -> 0 | L23: =IFERROR(VLOOKUP($A$3:$A$116,'[2]DEC-2026'!$A$4:$AEE$125,MATCH('FY-(26-27)Q3'!$K$2:$L$2,'[2]DEC-2026'!$A$2:$EF$2,0),0),0) -> 0 | M23: =G23+I23+K23 -> -566479 | N23: =H23+J23+L23 -> -2.4629522
A24: P3244 | B24: Jinesh Jain | C24: XTS41 | D24: Stock fo | F24: 0.2 | G24: =IFERROR(VLOOKUP($A$3:$A$116,'OCT-2026'!$A$4:$ADI$120,MATCH('FY-(26-27)Q3'!$G$2:$H$2,'OCT-2026'!$A$2:$DJ$2,0),0),0) -> 188991 | H24: =IFERROR(VLOOKUP($A$3:$A$116,'OCT-2026'!$A$4:$ADI$120,MATCH('FY-(26-27)Q3'!$G$2:$H$2,'OCT-2026'!$A$2:$DJ$2,0),0),0) -> 9.44955 | I24: =IFERROR(VLOOKUP($A$3:$A$116,'[1]NOV-2026'!$A$4:$ADL$124,MATCH('FY-(26-27)Q3'!$I$2:$J$2,'[1]NOV-2026'!$A$2:$DM$2,0),0),0) -> 0 | J24: =IFERROR(VLOOKUP($A$3:$A$116,'[1]NOV-2026'!$A$4:$ADL$124,MATCH('FY-(26-27)Q3'!$I$2:$J$2,'[1]NOV-2026'!$A$2:$DM$2,0),0),0) -> 0 | K24: =IFERROR(VLOOKUP($A$3:$A$116,'[2]DEC-2026'!$A$4:$AEE$125,MATCH('FY-(26-27)Q3'!$K$2:$L$2,'[2]DEC-2026'!$A$2:$EF$2,0),0),0) -> 0 | L24: =IFERROR(VLOOKUP($A$3:$A$116,'[2]DEC-2026'!$A$4:$AEE$125,MATCH('FY-(26-27)Q3'!$K$2:$L$2,'[2]DEC-2026'!$A$2:$EF$2,0),0),0) -> 0 | M24: =G24+I24+K24 -> 188991 | N24: =H24+J24+L24 -> 9.44955
A25: P3434 | B25: Kapil Kumar | C25: ATS_1529 | E25: NSEFO | F25: 0.2 | G25: =IFERROR(VLOOKUP($A$3:$A$116,'OCT-2026'!$A$4:$ADI$120,MATCH('FY-(26-27)Q3'!$G$2:$H$2,'OCT-2026'!$A$2:$DJ$2,0),0),0) -> -31804 | H25: =IFERROR(VLOOKUP($A$3:$A$116,'OCT-2026'!$A$4:$ADI$120,MATCH('FY-(26-27)Q3'!$G$2:$H$2,'OCT-2026'!$A$2:$DJ$2,0),0),0) -> -0.63608 | I25: =IFERROR(VLOOKUP($A$3:$A$116,'[1]NOV-2026'!$A$4:$ADL$124,MATCH('FY-(26-27)Q3'!$I$2:$J$2,'[1]NOV-2026'!$A$2:$DM$2,0),0),0) -> 0 | J25: =IFERROR(VLOOKUP($A$3:$A$116,'[1]NOV-2026'!$A$4:$ADL$124,MATCH('FY-(26-27)Q3'!$I$2:$J$2,'[1]NOV-2026'!$A$2:$DM$2,0),0),0) -> 0 | K25: =IFERROR(VLOOKUP($A$3:$A$116,'[2]DEC-2026'!$A$4:$AEE$125,MATCH('FY-(26-27)Q3'!$K$2:$L$2,'[2]DEC-2026'!$A$2:$EF$2,0),0),0) -> 0 | L25: =IFERROR(VLOOKUP($A$3:$A$116,'[2]DEC-2026'!$A$4:$AEE$125,MATCH('FY-(26-27)Q3'!$K$2:$L$2,'[2]DEC-2026'!$A$2:$EF$2,0),0),0) -> 0 | M25: =G25+I25+K25 -> -31804 | N25: =H25+J25+L25 -> -0.63608
A26: P2105 | B26: Kamlesh | C26: S1501 | D26: Wanda | E26: NSEFO | F26: 5 | G26: =IFERROR(VLOOKUP($A$3:$A$116,'OCT-2026'!$A$4:$ADI$120,MATCH('FY-(26-27)Q3'!$G$2:$H$2,'OCT-2026'!$A$2:$DJ$2,0),0),0) -> 1808800 | H26: =IFERROR(VLOOKUP($A$3:$A$116,'OCT-2026'!$A$4:$ADI$120,MATCH('FY-(26-27)Q3'!$G$2:$H$2,'OCT-2026'!$A$2:$DJ$2,0),0),0) -> 3.6176 | I26: =IFERROR(VLOOKUP($A$3:$A$116,'[1]NOV-2026'!$A$4:$ADL$124,MATCH('FY-(26-27)Q3'!$I$2:$J$2,'[1]NOV-2026'!$A$2:$DM$2,0),0),0) -> 0 | J26: =IFERROR(VLOOKUP($A$3:$A$116,'[1]NOV-2026'!$A$4:$ADL$124,MATCH('FY-(26-27)Q3'!$I$2:$J$2,'[1]NOV-2026'!$A$2:$DM$2,0),0),0) -> 0 | K26: =IFERROR(VLOOKUP($A$3:$A$116,'[2]DEC-2026'!$A$4:$AEE$125,MATCH('FY-(26-27)Q3'!$K$2:$L$2,'[2]DEC-2026'!$A$2:$EF$2,0),0),0) -> 0 | L26: =IFERROR(VLOOKUP($A$3:$A$116,'[2]DEC-2026'!$A$4:$AEE$125,MATCH('FY-(26-27)Q3'!$K$2:$L$2,'[2]DEC-2026'!$A$2:$EF$2,0),0),0) -> 0 | M26: =G26+I26+K26 -> 1808800 | N26: =H26+J26+L26 -> 3.6176
A27: P3024 | B27: Kartaram Pro | C27: ATS_1005 | D27: Spider 2.0 | E27: NSEFO | F27: 10 | G27: =IFERROR(VLOOKUP($A$3:$A$116,'OCT-2026'!$A$4:$ADI$120,MATCH('FY-(26-27)Q3'!$G$2:$H$2,'OCT-2026'!$A$2:$DJ$2,0),0),0) -> 225891 | H27: =IFERROR(VLOOKUP($A$3:$A$116,'OCT-2026'!$A$4:$ADI$120,MATCH('FY-(26-27)Q3'!$G$2:$H$2,'OCT-2026'!$A$2:$DJ$2,0),0),0) -> 0.225891 | I27: =IFERROR(VLOOKUP($A$3:$A$116,'[1]NOV-2026'!$A$4:$ADL$124,MATCH('FY-(26-27)Q3'!$I$2:$J$2,'[1]NOV-2026'!$A$2:$DM$2,0),0),0) -> 0 | J27: =IFERROR(VLOOKUP($A$3:$A$116,'[1]NOV-2026'!$A$4:$ADL$124,MATCH('FY-(26-27)Q3'!$I$2:$J$2,'[1]NOV-2026'!$A$2:$DM$2,0),0),0) -> 0 | K27: =IFERROR(VLOOKUP($A$3:$A$116,'[2]DEC-2026'!$A$4:$AEE$125,MATCH('FY-(26-27)Q3'!$K$2:$L$2,'[2]DEC-2026'!$A$2:$EF$2,0),0),0) -> 0 | L27: =IFERROR(VLOOKUP($A$3:$A$116,'[2]DEC-2026'!$A$4:$AEE$125,MATCH('FY-(26-27)Q3'!$K$2:$L$2,'[2]DEC-2026'!$A$2:$EF$2,0),0),0) -> 0 | M27: =G27+I27+K27 -> 225891 | N27: =H27+J27+L27 -> 0.225891
A28: P3446 | B28: Gargi Bharti | C28: ATS_1511 | E28: NSEFO | F28: 1 | G28: =IFERROR(VLOOKUP($A$3:$A$116,'OCT-2026'!$A$4:$ADI$120,MATCH('FY-(26-27)Q3'!$G$2:$H$2,'OCT-2026'!$A$2:$DJ$2,0),0),0) -> 28186 | H28: =IFERROR(VLOOKUP($A$3:$A$116,'OCT-2026'!$A$4:$ADI$120,MATCH('FY-(26-27)Q3'!$G$2:$H$2,'OCT-2026'!$A$2:$DJ$2,0),0),0) -> 0.56372 | I28: =IFERROR(VLOOKUP($A$3:$A$116,'[1]NOV-2026'!$A$4:$ADL$124,MATCH('FY-(26-27)Q3'!$I$2:$J$2,'[1]NOV-2026'!$A$2:$DM$2,0),0),0) -> 0 | J28: =IFERROR(VLOOKUP($A$3:$A$116,'[1]NOV-2026'!$A$4:$ADL$124,MATCH('FY-(26-27)Q3'!$I$2:$J$2,'[1]NOV-2026'!$A$2:$DM$2,0),0),0) -> 0 | K28: =IFERROR(VLOOKUP($A$3:$A$116,'[2]DEC-2026'!$A$4:$AEE$125,MATCH('FY-(26-27)Q3'!$K$2:$L$2,'[2]DEC-2026'!$A$2:$EF$2,0),0),0) -> 0 | L28: =IFERROR(VLOOKUP($A$3:$A$116,'[2]DEC-2026'!$A$4:$AEE$125,MATCH('FY-(26-27)Q3'!$K$2:$L$2,'[2]DEC-2026'!$A$2:$EF$2,0),0),0) -> 0 | M28: =G28+I28+K28 -> 28186 | N28: =H28+J28+L28 -> 0.56372
A29: P3202 | B29: Gagandeep | C29: XTS12 | D29: Gagandeep | E29: NSEFO | F29: 5 | G29: =IFERROR(VLOOKUP($A$3:$A$116,'OCT-2026'!$A$4:$ADI$120,MATCH('FY-(26-27)Q3'!$G$2:$H$2,'OCT-2026'!$A$2:$DJ$2,0),0),0) -> 841174 | H29: =IFERROR(VLOOKUP($A$3:$A$116,'OCT-2026'!$A$4:$ADI$120,MATCH('FY-(26-27)Q3'!$G$2:$H$2,'OCT-2026'!$A$2:$DJ$2,0),0),0) -> 1.682348 | I29: =IFERROR(VLOOKUP($A$3:$A$116,'[1]NOV-2026'!$A$4:$ADL$124,MATCH('FY-(26-27)Q3'!$I$2:$J$2,'[1]NOV-2026'!$A$2:$DM$2,0),0),0) -> 0 | J29: =IFERROR(VLOOKUP($A$3:$A$116,'[1]NOV-2026'!$A$4:$ADL$124,MATCH('FY-(26-27)Q3'!$I$2:$J$2,'[1]NOV-2026'!$A$2:$DM$2,0),0),0) -> 0 | K29: =IFERROR(VLOOKUP($A$3:$A$116,'[2]DEC-2026'!$A$4:$AEE$125,MATCH('FY-(26-27)Q3'!$K$2:$L$2,'[2]DEC-2026'!$A$2:$EF$2,0),0),0) -> 0 | L29: =IFERROR(VLOOKUP($A$3:$A$116,'[2]DEC-2026'!$A$4:$AEE$125,MATCH('FY-(26-27)Q3'!$K$2:$L$2,'[2]DEC-2026'!$A$2:$EF$2,0),0),0) -> 0 | M29: =G29+I29+K29 -> 841174 | N29: =H29+J29+L29 -> 1.682348
A30: P3020 | B30: Mahavir Jindal | C30: XTS02 | D30: Mahavir Jindal | E30: NSEFO | F30: 5 | G30: =IFERROR(VLOOKUP($A$3:$A$116,'OCT-2026'!$A$4:$ADI$120,MATCH('FY-(26-27)Q3'!$G$2:$H$2,'OCT-2026'!$A$2:$DJ$2,0),0),0) -> 140133 | H30: =IFERROR(VLOOKUP($A$3:$A$116,'OCT-2026'!$A$4:$ADI$120,MATCH('FY-(26-27)Q3'!$G$2:$H$2,'OCT-2026'!$A$2:$DJ$2,0),0),0) -> 0.280266 | I30: =IFERROR(VLOOKUP($A$3:$A$116,'[1]NOV-2026'!$A$4:$ADL$124,MATCH('FY-(26-27)Q3'!$I$2:$J$2,'[1]NOV-2026'!$A$2:$DM$2,0),0),0) -> 0 | J30: =IFERROR(VLOOKUP($A$3:$A$116,'[1]NOV-2026'!$A$4:$ADL$124,MATCH('FY-(26-27)Q3'!$I$2:$J$2,'[1]NOV-2026'!$A$2:$DM$2,0),0),0) -> 0 | K30: =IFERROR(VLOOKUP($A$3:$A$116,'[2]DEC-2026'!$A$4:$AEE$125,MATCH('FY-(26-27)Q3'!$K$2:$L$2,'[2]DEC-2026'!$A$2:$EF$2,0),0),0) -> 0 | L30: =IFERROR(VLOOKUP($A$3:$A$116,'[2]DEC-2026'!$A$4:$AEE$125,MATCH('FY-(26-27)Q3'!$K$2:$L$2,'[2]DEC-2026'!$A$2:$EF$2,0),0),0) -> 0 | M30: =G30+I30+K30 -> 140133 | N30: =H30+J30+L30 -> 0.280266
A31: P3341 | B31: Maneesh Yadav | C31: XTS18 | D31: Theta Dominance | E31: NSEFO | F31: 0.5 | G31: =IFERROR(VLOOKUP($A$3:$A$116,'OCT-2026'!$A$4:$ADI$120,MATCH('FY-(26-27)Q3'!$G$2:$H$2,'OCT-2026'!$A$2:$DJ$2,0),0),0) -> 43166 | H31: =IFERROR(VLOOKUP($A$3:$A$116,'OCT-2026'!$A$4:$ADI$120,MATCH('FY-(26-27)Q3'!$G$2:$H$2,'OCT-2026'!$A$2:$DJ$2,0),0),0) -> 0.86332 | I31: =IFERROR(VLOOKUP($A$3:$A$116,'[1]NOV-2026'!$A$4:$ADL$124,MATCH('FY-(26-27)Q3'!$I$2:$J$2,'[1]NOV-2026'!$A$2:$DM$2,0),0),0) -> 0 | J31: =IFERROR(VLOOKUP($A$3:$A$116,'[1]NOV-2026'!$A$4:$ADL$124,MATCH('FY-(26-27)Q3'!$I$2:$J$2,'[1]NOV-2026'!$A$2:$DM$2,0),0),0) -> 0 | K31: =IFERROR(VLOOKUP($A$3:$A$116,'[2]DEC-2026'!$A$4:$AEE$125,MATCH('FY-(26-27)Q3'!$K$2:$L$2,'[2]DEC-2026'!$A$2:$EF$2,0),0),0) -> 0 | L31: =IFERROR(VLOOKUP($A$3:$A$116,'[2]DEC-2026'!$A$4:$AEE$125,MATCH('FY-(26-27)Q3'!$K$2:$L$2,'[2]DEC-2026'!$A$2:$EF$2,0),0),0) -> 0 | M31: =G31+I31+K31 -> 43166 | N31: =H31+J31+L31 -> 0.86332
A32: P2971_2 | B32: Neeraj Garg_2 | C32: S1514 | D32: ACE1 | E32: NSEFO | F32: 0.4 | G32: =IFERROR(VLOOKUP($A$3:$A$116,'OCT-2026'!$A$4:$ADI$120,MATCH('FY-(26-27)Q3'!$G$2:$H$2,'OCT-2026'!$A$2:$DJ$2,0),0),0) -> 344037 | H32: =IFERROR(VLOOKUP($A$3:$A$116,'OCT-2026'!$A$4:$ADI$120,MATCH('FY-(26-27)Q3'!$G$2:$H$2,'OCT-2026'!$A$2:$DJ$2,0),0),0) -> 8.600925 | I32: =IFERROR(VLOOKUP($A$3:$A$116,'[1]NOV-2026'!$A$4:$ADL$124,MATCH('FY-(26-27)Q3'!$I$2:$J$2,'[1]NOV-2026'!$A$2:$DM$2,0),0),0) -> 0 | J32: =IFERROR(VLOOKUP($A$3:$A$116,'[1]NOV-2026'!$A$4:$ADL$124,MATCH('FY-(26-27)Q3'!$I$2:$J$2,'[1]NOV-2026'!$A$2:$DM$2,0),0),0) -> 0 | K32: =IFERROR(VLOOKUP($A$3:$A$116,'[2]DEC-2026'!$A$4:$AEE$125,MATCH('FY-(26-27)Q3'!$K$2:$L$2,'[2]DEC-2026'!$A$2:$EF$2,0),0),0) -> 0 | L32: =IFERROR(VLOOKUP($A$3:$A$116,'[2]DEC-2026'!$A$4:$AEE$125,MATCH('FY-(26-27)Q3'!$K$2:$L$2,'[2]DEC-2026'!$A$2:$EF$2,0),0),0) -> 0 | M32: =G32+I32+K32 -> 344037 | N32: =H32+J32+L32 -> 8.600925
A33: P3070 | B33: Prateek | C33: ATS_1504 | D33: Smart Strangle | E33: NSEFO | F33: 4 | G33: =IFERROR(VLOOKUP($A$3:$A$116,'OCT-2026'!$A$4:$ADI$120,MATCH('FY-(26-27)Q3'!$G$2:$H$2,'OCT-2026'!$A$2:$DJ$2,0),0),0) -> 311005 | H33: =IFERROR(VLOOKUP($A$3:$A$116,'OCT-2026'!$A$4:$ADI$120,MATCH('FY-(26-27)Q3'!$G$2:$H$2,'OCT-2026'!$A$2:$DJ$2,0),0),0) -> 0.7775125 | I33: =IFERROR(VLOOKUP($A$3:$A$116,'[1]NOV-2026'!$A$4:$ADL$124,MATCH('FY-(26-27)Q3'!$I$2:$J$2,'[1]NOV-2026'!$A$2:$DM$2,0),0),0) -> 0 | J33: =IFERROR(VLOOKUP($A$3:$A$116,'[1]NOV-2026'!$A$4:$ADL$124,MATCH('FY-(26-27)Q3'!$I$2:$J$2,'[1]NOV-2026'!$A$2:$DM$2,0),0),0) -> 0 | K33: =IFERROR(VLOOKUP($A$3:$A$116,'[2]DEC-2026'!$A$4:$AEE$125,MATCH('FY-(26-27)Q3'!$K$2:$L$2,'[2]DEC-2026'!$A$2:$EF$2,0),0),0) -> 0 | L33: =IFERROR(VLOOKUP($A$3:$A$116,'[2]DEC-2026'!$A$4:$AEE$125,MATCH('FY-(26-27)Q3'!$K$2:$L$2,'[2]DEC-2026'!$A$2:$EF$2,0),0),0) -> 0 | M33: =G33+I33+K33 -> 311005 | N33: =H33+J33+L33 -> 0.7775125
A34: P2999 | B34: Prateek | C34: ATS_1519 | D34: ETF | E34: ETF | F34: 1 | G34: =IFERROR(VLOOKUP($A$3:$A$116,'OCT-2026'!$A$4:$ADI$120,MATCH('FY-(26-27)Q3'!$G$2:$H$2,'OCT-2026'!$A$2:$DJ$2,0),0),0) -> -36765 | H34: =IFERROR(VLOOKUP($A$3:$A$116,'OCT-2026'!$A$4:$ADI$120,MATCH('FY-(26-27)Q3'!$G$2:$H$2,'OCT-2026'!$A$2:$DJ$2,0),0),0) -> -0.36765 | I34: =IFERROR(VLOOKUP($A$3:$A$116,'[1]NOV-2026'!$A$4:$ADL$124,MATCH('FY-(26-27)Q3'!$I$2:$J$2,'[1]NOV-2026'!$A$2:$DM$2,0),0),0) -> 0 | J34: =IFERROR(VLOOKUP($A$3:$A$116,'[1]NOV-2026'!$A$4:$ADL$124,MATCH('FY-(26-27)Q3'!$I$2:$J$2,'[1]NOV-2026'!$A$2:$DM$2,0),0),0) -> 0 | K34: =IFERROR(VLOOKUP($A$3:$A$116,'[2]DEC-2026'!$A$4:$AEE$125,MATCH('FY-(26-27)Q3'!$K$2:$L$2,'[2]DEC-2026'!$A$2:$EF$2,0),0),0) -> 0 | L34: =IFERROR(VLOOKUP($A$3:$A$116,'[2]DEC-2026'!$A$4:$AEE$125,MATCH('FY-(26-27)Q3'!$K$2:$L$2,'[2]DEC-2026'!$A$2:$EF$2,0),0),0) -> 0 | M34: =G34+I34+K34 -> -36765 | N34: =H34+J34+L34 -> -0.36765
A35: P3000 | B35: Prateek | C35: XTS19 | D35: NSEFO | E35: NSEFO | G35: =IFERROR(VLOOKUP($A$3:$A$116,'OCT-2026'!$A$4:$ADI$120,MATCH('FY-(26-27)Q3'!$G$2:$H$2,'OCT-2026'!$A$2:$DJ$2,0),0),0) -> 0 | H35: =IFERROR(VLOOKUP($A$3:$A$116,'OCT-2026'!$A$4:$ADI$120,MATCH('FY-(26-27)Q3'!$G$2:$H$2,'OCT-2026'!$A$2:$DJ$2,0),0),0) -> 0 | I35: =IFERROR(VLOOKUP($A$3:$A$116,'[1]NOV-2026'!$A$4:$ADL$124,MATCH('FY-(26-27)Q3'!$I$2:$J$2,'[1]NOV-2026'!$A$2:$DM$2,0),0),0) -> 0 | J35: =IFERROR(VLOOKUP($A$3:$A$116,'[1]NOV-2026'!$A$4:$ADL$124,MATCH('FY-(26-27)Q3'!$I$2:$J$2,'[1]NOV-2026'!$A$2:$DM$2,0),0),0) -> 0 | K35: =IFERROR(VLOOKUP($A$3:$A$116,'[2]DEC-2026'!$A$4:$AEE$125,MATCH('FY-(26-27)Q3'!$K$2:$L$2,'[2]DEC-2026'!$A$2:$EF$2,0),0),0) -> 0 | L35: =IFERROR(VLOOKUP($A$3:$A$116,'[2]DEC-2026'!$A$4:$AEE$125,MATCH('FY-(26-27)Q3'!$K$2:$L$2,'[2]DEC-2026'!$A$2:$EF$2,0),0),0) -> 0 | M35: =G35+I35+K35 -> 0 | N35: =H35+J35+L35 -> 0
A36: P3186 | B36: Prateek | C36: XTS17 | D36: opton | E36: NSEFO | F36: 0.5 | G36: =IFERROR(VLOOKUP($A$3:$A$116,'OCT-2026'!$A$4:$ADI$120,MATCH('FY-(26-27)Q3'!$G$2:$H$2,'OCT-2026'!$A$2:$DJ$2,0),0),0) -> -42052 | H36: =IFERROR(VLOOKUP($A$3:$A$116,'OCT-2026'!$A$4:$ADI$120,MATCH('FY-(26-27)Q3'!$G$2:$H$2,'OCT-2026'!$A$2:$DJ$2,0),0),0) -> -0.84104 | I36: =IFERROR(VLOOKUP($A$3:$A$116,'[1]NOV-2026'!$A$4:$ADL$124,MATCH('FY-(26-27)Q3'!$I$2:$J$2,'[1]NOV-2026'!$A$2:$DM$2,0),0),0) -> 0 | J36: =IFERROR(VLOOKUP($A$3:$A$116,'[1]NOV-2026'!$A$4:$ADL$124,MATCH('FY-(26-27)Q3'!$I$2:$J$2,'[1]NOV-2026'!$A$2:$DM$2,0),0),0) -> 0 | K36: =IFERROR(VLOOKUP($A$3:$A$116,'[2]DEC-2026'!$A$4:$AEE$125,MATCH('FY-(26-27)Q3'!$K$2:$L$2,'[2]DEC-2026'!$A$2:$EF$2,0),0),0) -> 0 | L36: =IFERROR(VLOOKUP($A$3:$A$116,'[2]DEC-2026'!$A$4:$AEE$125,MATCH('FY-(26-27)Q3'!$K$2:$L$2,'[2]DEC-2026'!$A$2:$EF$2,0),0),0) -> 0 | M36: =G36+I36+K36 -> -42052 | N36: =H36+J36+L36 -> -0.84104
A37: P3135 | B37: Piyush Singhal | C37: ATS_1509 | D37: Direction range | E37: NSEFO | F37: 1 | G37: =IFERROR(VLOOKUP($A$3:$A$116,'OCT-2026'!$A$4:$ADI$120,MATCH('FY-(26-27)Q3'!$G$2:$H$2,'OCT-2026'!$A$2:$DJ$2,0),0),0) -> 422121 | H37: =IFERROR(VLOOKUP($A$3:$A$116,'OCT-2026'!$A$4:$ADI$120,MATCH('FY-(26-27)Q3'!$G$2:$H$2,'OCT-2026'!$A$2:$DJ$2,0),0),0) -> 1.40707 | I37: =IFERROR(VLOOKUP($A$3:$A$116,'[1]NOV-2026'!$A$4:$ADL$124,MATCH('FY-(26-27)Q3'!$I$2:$J$2,'[1]NOV-2026'!$A$2:$DM$2,0),0),0) -> 0 | J37: =IFERROR(VLOOKUP($A$3:$A$116,'[1]NOV-2026'!$A$4:$ADL$124,MATCH('FY-(26-27)Q3'!$I$2:$J$2,'[1]NOV-2026'!$A$2:$DM$2,0),0),0) -> 0 | K37: =IFERROR(VLOOKUP($A$3:$A$116,'[2]DEC-2026'!$A$4:$AEE$125,MATCH('FY-(26-27)Q3'!$K$2:$L$2,'[2]DEC-2026'!$A$2:$EF$2,0),0),0) -> 0 | L37: =IFERROR(VLOOKUP($A$3:$A$116,'[2]DEC-2026'!$A$4:$AEE$125,MATCH('FY-(26-27)Q3'!$K$2:$L$2,'[2]DEC-2026'!$A$2:$EF$2,0),0),0) -> 0 | M37: =G37+I37+K37 -> 422121 | N37: =H37+J37+L37 -> 1.40707
A38: P3152 | B38: Rashil Khetan | C38: XTS29 | E38: NSEFO | F38: 0.1 | G38: =IFERROR(VLOOKUP($A$3:$A$116,'OCT-2026'!$A$4:$ADI$120,MATCH('FY-(26-27)Q3'!$G$2:$H$2,'OCT-2026'!$A$2:$DJ$2,0),0),0) -> -191569 | H38: =IFERROR(VLOOKUP($A$3:$A$116,'OCT-2026'!$A$4:$ADI$120,MATCH('FY-(26-27)Q3'!$G$2:$H$2,'OCT-2026'!$A$2:$DJ$2,0),0),0) -> -19.1569 | I38: =IFERROR(VLOOKUP($A$3:$A$116,'[1]NOV-2026'!$A$4:$ADL$124,MATCH('FY-(26-27)Q3'!$I$2:$J$2,'[1]NOV-2026'!$A$2:$DM$2,0),0),0) -> 0 | J38: =IFERROR(VLOOKUP($A$3:$A$116,'[1]NOV-2026'!$A$4:$ADL$124,MATCH('FY-(26-27)Q3'!$I$2:$J$2,'[1]NOV-2026'!$A$2:$DM$2,0),0),0) -> 0 | K38: =IFERROR(VLOOKUP($A$3:$A$116,'[2]DEC-2026'!$A$4:$AEE$125,MATCH('FY-(26-27)Q3'!$K$2:$L$2,'[2]DEC-2026'!$A$2:$EF$2,0),0),0) -> 0 | L38: =IFERROR(VLOOKUP($A$3:$A$116,'[2]DEC-2026'!$A$4:$AEE$125,MATCH('FY-(26-27)Q3'!$K$2:$L$2,'[2]DEC-2026'!$A$2:$EF$2,0),0),0) -> 0 | M38: =G38+I38+K38 -> -191569 | N38: =H38+J38+L38 -> -19.1569
A39: P3342 | B39: Raghav Tuli | C39: XTS20 | D39: Flaxi trade | E39: NSEFO | F39: 1 | G39: =IFERROR(VLOOKUP($A$3:$A$116,'OCT-2026'!$A$4:$ADI$120,MATCH('FY-(26-27)Q3'!$G$2:$H$2,'OCT-2026'!$A$2:$DJ$2,0),0),0) -> 75358 | H39: =IFERROR(VLOOKUP($A$3:$A$116,'OCT-2026'!$A$4:$ADI$120,MATCH('FY-(26-27)Q3'!$G$2:$H$2,'OCT-2026'!$A$2:$DJ$2,0),0),0) -> 1.50716 | I39: =IFERROR(VLOOKUP($A$3:$A$116,'[1]NOV-2026'!$A$4:$ADL$124,MATCH('FY-(26-27)Q3'!$I$2:$J$2,'[1]NOV-2026'!$A$2:$DM$2,0),0),0) -> 0 | J39: =IFERROR(VLOOKUP($A$3:$A$116,'[1]NOV-2026'!$A$4:$ADL$124,MATCH('FY-(26-27)Q3'!$I$2:$J$2,'[1]NOV-2026'!$A$2:$DM$2,0),0),0) -> 0 | K39: =IFERROR(VLOOKUP($A$3:$A$116,'[2]DEC-2026'!$A$4:$AEE$125,MATCH('FY-(26-27)Q3'!$K$2:$L$2,'[2]DEC-2026'!$A$2:$EF$2,0),0),0) -> 0 | L39: =IFERROR(VLOOKUP($A$3:$A$116,'[2]DEC-2026'!$A$4:$AEE$125,MATCH('FY-(26-27)Q3'!$K$2:$L$2,'[2]DEC-2026'!$A$2:$EF$2,0),0),0) -> 0 | M39: =G39+I39+K39 -> 75358 | N39: =H39+J39+L39 -> 1.50716
A40: P3082 | B40: Ramakar Jha | C40: ATS1012 | D40: CASH | E40: CASH | F40: 1 | G40: =IFERROR(VLOOKUP($A$3:$A$116,'OCT-2026'!$A$4:$ADI$120,MATCH('FY-(26-27)Q3'!$G$2:$H$2,'OCT-2026'!$A$2:$DJ$2,0),0),0) -> -747613 | H40: =IFERROR(VLOOKUP($A$3:$A$116,'OCT-2026'!$A$4:$ADI$120,MATCH('FY-(26-27)Q3'!$G$2:$H$2,'OCT-2026'!$A$2:$DJ$2,0),0),0) -> -7.47613 | I40: =IFERROR(VLOOKUP($A$3:$A$116,'[1]NOV-2026'!$A$4:$ADL$124,MATCH('FY-(26-27)Q3'!$I$2:$J$2,'[1]NOV-2026'!$A$2:$DM$2,0),0),0) -> 0 | J40: =IFERROR(VLOOKUP($A$3:$A$116,'[1]NOV-2026'!$A$4:$ADL$124,MATCH('FY-(26-27)Q3'!$I$2:$J$2,'[1]NOV-2026'!$A$2:$DM$2,0),0),0) -> 0 | K40: =IFERROR(VLOOKUP($A$3:$A$116,'[2]DEC-2026'!$A$4:$AEE$125,MATCH('FY-(26-27)Q3'!$K$2:$L$2,'[2]DEC-2026'!$A$2:$EF$2,0),0),0) -> 0 | L40: =IFERROR(VLOOKUP($A$3:$A$116,'[2]DEC-2026'!$A$4:$AEE$125,MATCH('FY-(26-27)Q3'!$K$2:$L$2,'[2]DEC-2026'!$A$2:$EF$2,0),0),0) -> 0 | M40: =G40+I40+K40 -> -747613 | N40: =H40+J40+L40 -> -7.47613
A41: P3058 | B41: Ramakar Jha | C41: ATS_1513 | D41: Stock fo | E41: NSEFO | F41: 0.5 | G41: =IFERROR(VLOOKUP($A$3:$A$116,'OCT-2026'!$A$4:$ADI$120,MATCH('FY-(26-27)Q3'!$G$2:$H$2,'OCT-2026'!$A$2:$DJ$2,0),0),0) -> 547590 | H41: =IFERROR(VLOOKUP($A$3:$A$116,'OCT-2026'!$A$4:$ADI$120,MATCH('FY-(26-27)Q3'!$G$2:$H$2,'OCT-2026'!$A$2:$DJ$2,0),0),0) -> 10.9518 | I41: =IFERROR(VLOOKUP($A$3:$A$116,'[1]NOV-2026'!$A$4:$ADL$124,MATCH('FY-(26-27)Q3'!$I$2:$J$2,'[1]NOV-2026'!$A$2:$DM$2,0),0),0) -> 0 | J41: =IFERROR(VLOOKUP($A$3:$A$116,'[1]NOV-2026'!$A$4:$ADL$124,MATCH('FY-(26-27)Q3'!$I$2:$J$2,'[1]NOV-2026'!$A$2:$DM$2,0),0),0) -> 0 | K41: =IFERROR(VLOOKUP($A$3:$A$116,'[2]DEC-2026'!$A$4:$AEE$125,MATCH('FY-(26-27)Q3'!$K$2:$L$2,'[2]DEC-2026'!$A$2:$EF$2,0),0),0) -> 0 | L41: =IFERROR(VLOOKUP($A$3:$A$116,'[2]DEC-2026'!$A$4:$AEE$125,MATCH('FY-(26-27)Q3'!$K$2:$L$2,'[2]DEC-2026'!$A$2:$EF$2,0),0),0) -> 0 | M41: =G41+I41+K41 -> 547590 | N41: =H41+J41+L41 -> 10.9518
A42: P3433 | B42: Sanchit | C42: ATS_1528 | E42: NSEFO | F42: 0.1 | G42: =IFERROR(VLOOKUP($A$3:$A$116,'OCT-2026'!$A$4:$ADI$120,MATCH('FY-(26-27)Q3'!$G$2:$H$2,'OCT-2026'!$A$2:$DJ$2,0),0),0) -> -30785 | H42: =IFERROR(VLOOKUP($A$3:$A$116,'OCT-2026'!$A$4:$ADI$120,MATCH('FY-(26-27)Q3'!$G$2:$H$2,'OCT-2026'!$A$2:$DJ$2,0),0),0) -> -0.6157 | I42: =IFERROR(VLOOKUP($A$3:$A$116,'[1]NOV-2026'!$A$4:$ADL$124,MATCH('FY-(26-27)Q3'!$I$2:$J$2,'[1]NOV-2026'!$A$2:$DM$2,0),0),0) -> 0 | J42: =IFERROR(VLOOKUP($A$3:$A$116,'[1]NOV-2026'!$A$4:$ADL$124,MATCH('FY-(26-27)Q3'!$I$2:$J$2,'[1]NOV-2026'!$A$2:$DM$2,0),0),0) -> 0 | K42: =IFERROR(VLOOKUP($A$3:$A$116,'[2]DEC-2026'!$A$4:$AEE$125,MATCH('FY-(26-27)Q3'!$K$2:$L$2,'[2]DEC-2026'!$A$2:$EF$2,0),0),0) -> 0 | L42: =IFERROR(VLOOKUP($A$3:$A$116,'[2]DEC-2026'!$A$4:$AEE$125,MATCH('FY-(26-27)Q3'!$K$2:$L$2,'[2]DEC-2026'!$A$2:$EF$2,0),0),0) -> 0 | M42: =G42+I42+K42 -> -30785 | N42: =H42+J42+L42 -> -0.6157
A43: P3048 | B43: Shahid | C43: XTS05 | D43: Shahid | E43: NSEFO | F43: 1 | G43: =IFERROR(VLOOKUP($A$3:$A$116,'OCT-2026'!$A$4:$ADI$120,MATCH('FY-(26-27)Q3'!$G$2:$H$2,'OCT-2026'!$A$2:$DJ$2,0),0),0) -> 1105039 | H43: =IFERROR(VLOOKUP($A$3:$A$116,'OCT-2026'!$A$4:$ADI$120,MATCH('FY-(26-27)Q3'!$G$2:$H$2,'OCT-2026'!$A$2:$DJ$2,0),0),0) -> 3.6834633 | I43: =IFERROR(VLOOKUP($A$3:$A$116,'[1]NOV-2026'!$A$4:$ADL$124,MATCH('FY-(26-27)Q3'!$I$2:$J$2,'[1]NOV-2026'!$A$2:$DM$2,0),0),0) -> 0 | J43: =IFERROR(VLOOKUP($A$3:$A$116,'[1]NOV-2026'!$A$4:$ADL$124,MATCH('FY-(26-27)Q3'!$I$2:$J$2,'[1]NOV-2026'!$A$2:$DM$2,0),0),0) -> 0 | K43: =IFERROR(VLOOKUP($A$3:$A$116,'[2]DEC-2026'!$A$4:$AEE$125,MATCH('FY-(26-27)Q3'!$K$2:$L$2,'[2]DEC-2026'!$A$2:$EF$2,0),0),0) -> 0 | L43: =IFERROR(VLOOKUP($A$3:$A$116,'[2]DEC-2026'!$A$4:$AEE$125,MATCH('FY-(26-27)Q3'!$K$2:$L$2,'[2]DEC-2026'!$A$2:$EF$2,0),0),0) -> 0 | M43: =G43+I43+K43 -> 1105039 | N43: =H43+J43+L43 -> 3.6834633
A44: P3335 | B44: Sajal Sharma | F44: 1 | G44: =IFERROR(VLOOKUP($A$3:$A$116,'OCT-2026'!$A$4:$ADI$120,MATCH('FY-(26-27)Q3'!$G$2:$H$2,'OCT-2026'!$A$2:$DJ$2,0),0),0) -> 0 | H44: =IFERROR(VLOOKUP($A$3:$A$116,'OCT-2026'!$A$4:$ADI$120,MATCH('FY-(26-27)Q3'!$G$2:$H$2,'OCT-2026'!$A$2:$DJ$2,0),0),0) -> 0 | I44: =IFERROR(VLOOKUP($A$3:$A$116,'[1]NOV-2026'!$A$4:$ADL$124,MATCH('FY-(26-27)Q3'!$I$2:$J$2,'[1]NOV-2026'!$A$2:$DM$2,0),0),0) -> 0 | J44: =IFERROR(VLOOKUP($A$3:$A$116,'[1]NOV-2026'!$A$4:$ADL$124,MATCH('FY-(26-27)Q3'!$I$2:$J$2,'[1]NOV-2026'!$A$2:$DM$2,0),0),0) -> 0 | K44: =IFERROR(VLOOKUP($A$3:$A$116,'[2]DEC-2026'!$A$4:$AEE$125,MATCH('FY-(26-27)Q3'!$K$2:$L$2,'[2]DEC-2026'!$A$2:$EF$2,0),0),0) -> 0 | L44: =IFERROR(VLOOKUP($A$3:$A$116,'[2]DEC-2026'!$A$4:$AEE$125,MATCH('FY-(26-27)Q3'!$K$2:$L$2,'[2]DEC-2026'!$A$2:$EF$2,0),0),0) -> 0 | M44: =G44+I44+K44 -> 0 | N44: =H44+J44+L44 -> 0
A45: P3208 | B45: Sajal Sharma | C45: ODIN | D45: BSEFO | E45: BSEFO | F45: 4 | G45: =IFERROR(VLOOKUP($A$3:$A$116,'OCT-2026'!$A$4:$ADI$120,MATCH('FY-(26-27)Q3'!$G$2:$H$2,'OCT-2026'!$A$2:$DJ$2,0),0),0) -> 85710 | H45: =IFERROR(VLOOKUP($A$3:$A$116,'OCT-2026'!$A$4:$ADI$120,MATCH('FY-(26-27)Q3'!$G$2:$H$2,'OCT-2026'!$A$2:$DJ$2,0),0),0) -> 0.214275 | I45: =IFERROR(VLOOKUP($A$3:$A$116,'[1]NOV-2026'!$A$4:$ADL$124,MATCH('FY-(26-27)Q3'!$I$2:$J$2,'[1]NOV-2026'!$A$2:$DM$2,0),0),0) -> 0 | J45: =IFERROR(VLOOKUP($A$3:$A$116,'[1]NOV-2026'!$A$4:$ADL$124,MATCH('FY-(26-27)Q3'!$I$2:$J$2,'[1]NOV-2026'!$A$2:$DM$2,0),0),0) -> 0 | K45: =IFERROR(VLOOKUP($A$3:$A$116,'[2]DEC-2026'!$A$4:$AEE$125,MATCH('FY-(26-27)Q3'!$K$2:$L$2,'[2]DEC-2026'!$A$2:$EF$2,0),0),0) -> 0 | L45: =IFERROR(VLOOKUP($A$3:$A$116,'[2]DEC-2026'!$A$4:$AEE$125,MATCH('FY-(26-27)Q3'!$K$2:$L$2,'[2]DEC-2026'!$A$2:$EF$2,0),0),0) -> 0 | M45: =G45+I45+K45 -> 85710 | N45: =H45+J45+L45 -> 0.214275
A46: P3119 | B46: Sajal Sharma | C46: ODIN | D46: NSE FO | E46: NSEFO | F46: 4 | G46: =IFERROR(VLOOKUP($A$3:$A$116,'OCT-2026'!$A$4:$ADI$120,MATCH('FY-(26-27)Q3'!$G$2:$H$2,'OCT-2026'!$A$2:$DJ$2,0),0),0) -> 204861 | H46: =IFERROR(VLOOKUP($A$3:$A$116,'OCT-2026'!$A$4:$ADI$120,MATCH('FY-(26-27)Q3'!$G$2:$H$2,'OCT-2026'!$A$2:$DJ$2,0),0),0) -> 0.5121525 | I46: =IFERROR(VLOOKUP($A$3:$A$116,'[1]NOV-2026'!$A$4:$ADL$124,MATCH('FY-(26-27)Q3'!$I$2:$J$2,'[1]NOV-2026'!$A$2:$DM$2,0),0),0) -> 0 | J46: =IFERROR(VLOOKUP($A$3:$A$116,'[1]NOV-2026'!$A$4:$ADL$124,MATCH('FY-(26-27)Q3'!$I$2:$J$2,'[1]NOV-2026'!$A$2:$DM$2,0),0),0) -> 0 | K46: =IFERROR(VLOOKUP($A$3:$A$116,'[2]DEC-2026'!$A$4:$AEE$125,MATCH('FY-(26-27)Q3'!$K$2:$L$2,'[2]DEC-2026'!$A$2:$EF$2,0),0),0) -> 0 | L46: =IFERROR(VLOOKUP($A$3:$A$116,'[2]DEC-2026'!$A$4:$AEE$125,MATCH('FY-(26-27)Q3'!$K$2:$L$2,'[2]DEC-2026'!$A$2:$EF$2,0),0),0) -> 0 | M46: =G46+I46+K46 -> 204861 | N46: =H46+J46+L46 -> 0.5121525
A47: P3417 | B47: Sourav | C47: XTS38 | E47: NSEFO | F47: 0.1 | G47: =IFERROR(VLOOKUP($A$3:$A$116,'OCT-2026'!$A$4:$ADI$120,MATCH('FY-(26-27)Q3'!$G$2:$H$2,'OCT-2026'!$A$2:$DJ$2,0),0),0) -> -2957840 | H47: =IFERROR(VLOOKUP($A$3:$A$116,'OCT-2026'!$A$4:$ADI$120,MATCH('FY-(26-27)Q3'!$G$2:$H$2,'OCT-2026'!$A$2:$DJ$2,0),0),0) -> -2.95784 | I47: =IFERROR(VLOOKUP($A$3:$A$116,'[1]NOV-2026'!$A$4:$ADL$124,MATCH('FY-(26-27)Q3'!$I$2:$J$2,'[1]NOV-2026'!$A$2:$DM$2,0),0),0) -> 0 | J47: =IFERROR(VLOOKUP($A$3:$A$116,'[1]NOV-2026'!$A$4:$ADL$124,MATCH('FY-(26-27)Q3'!$I$2:$J$2,'[1]NOV-2026'!$A$2:$DM$2,0),0),0) -> 0 | K47: =IFERROR(VLOOKUP($A$3:$A$116,'[2]DEC-2026'!$A$4:$AEE$125,MATCH('FY-(26-27)Q3'!$K$2:$L$2,'[2]DEC-2026'!$A$2:$EF$2,0),0),0) -> 0 | L47: =IFERROR(VLOOKUP($A$3:$A$116,'[2]DEC-2026'!$A$4:$AEE$125,MATCH('FY-(26-27)Q3'!$K$2:$L$2,'[2]DEC-2026'!$A$2:$EF$2,0),0),0) -> 0 | M47: =G47+I47+K47 -> -2957840 | N47: =H47+J47+L47 -> -2.95784
B48: Sourav | C48: XTS31 | E48: NSEFO | G48: =IFERROR(VLOOKUP($A$3:$A$116,'OCT-2026'!$A$4:$ADI$120,MATCH('FY-(26-27)Q3'!$G$2:$H$2,'OCT-2026'!$A$2:$DJ$2,0),0),0) -> 0 | H48: =IFERROR(VLOOKUP($A$3:$A$116,'OCT-2026'!$A$4:$ADI$120,MATCH('FY-(26-27)Q3'!$G$2:$H$2,'OCT-2026'!$A$2:$DJ$2,0),0),0) -> 0 | I48: =IFERROR(VLOOKUP($A$3:$A$116,'[1]NOV-2026'!$A$4:$ADL$124,MATCH('FY-(26-27)Q3'!$I$2:$J$2,'[1]NOV-2026'!$A$2:$DM$2,0),0),0) -> 0 | J48: =IFERROR(VLOOKUP($A$3:$A$116,'[1]NOV-2026'!$A$4:$ADL$124,MATCH('FY-(26-27)Q3'!$I$2:$J$2,'[1]NOV-2026'!$A$2:$DM$2,0),0),0) -> 0 | K48: =IFERROR(VLOOKUP($A$3:$A$116,'[2]DEC-2026'!$A$4:$AEE$125,MATCH('FY-(26-27)Q3'!$K$2:$L$2,'[2]DEC-2026'!$A$2:$EF$2,0),0),0) -> 0 | L48: =IFERROR(VLOOKUP($A$3:$A$116,'[2]DEC-2026'!$A$4:$AEE$125,MATCH('FY-(26-27)Q3'!$K$2:$L$2,'[2]DEC-2026'!$A$2:$EF$2,0),0),0) -> 0 | M48: =G48+I48+K48 -> 0 | N48: =H48+J48+L48 -> 0
...

Sheet SEP-2026
H2: 46266 | I2: 46267 | J2: 46268 | K2: 46269 | L2: 46272 | M2: 46273 | N2: 46274 | O2: 46275 | P2: 46276 | Q2: 46280 | R2: 46281 | S2: 46282 | T2: 46283 | U2: 46286 | V2: 46287 | W2: 46288 | X2: 46289 | Y2: 46290 | Z2: 46293 | AA2: 46294 | AB2: 46295 | AC2: SEP | AD2: SEP ROI
A3: CODE | B3: NAME | C3: ID | D3: STRATEGY | E3: SEGMENT | F3: FUND | H3: TUE | I3: WED | J3: THU | K3: FRI | L3: MON | M3: TUE | N3: WED | O3: THU | P3: Fri | Q3: TUE | R3: WED | S3: THU | T3: FRI | U3: MON | V3: TUE | W3: WED | X3: THU | Y3: FRI | Z3: MON | AA3: TUE | AB3: WED | AK3: OPT | AL3: 13780
A4: P3389 | B4: Abdul | C4: XTS09 | D4: ATR-Strangle | E4: NSEFO | F4: 0.5 | H4: 0 | I4: -13362 | J4: 1600 | K4: -649 | L4: 8090 | M4: 5321 | N4: -27681 | O4: -22117 | P4: -1063 | Q4: 9212 | R4: -149 | S4: -21850 | T4: -420855 | U4: 34091 | V4: -25668 | W4: -1331 | X4: -14264 | Y4: -17150 | Z4: 53417 | AA4: 3780 | AB4: -26466 | AC4: =SUM(H4:AB4) -> -477094 | AD4: =IFERROR(AC4/F4*100,0)/10000000 -> -9.54188 | AK4: FUTURE EXP | AL4: 2865
A5: P2951 | B5: Aman Aggarwal | C5: XTS01 | D5: 20_60 | E5: NSEFO | F5: 3 | H5: -170827 | I5: 31407 | J5: 31240 | K5: 73349 | L5: 38045 | M5: 22400 | N5: -11568 | O5: 80488 | P5: -190900 | Q5: 182819 | R5: 81831 | S5: -92500 | T5: 144762 | U5: 32233 | V5: -100079 | W5: 59283 | X5: -163262 | Y5: 14537 | Z5: 225020 | AA5: 0 | AB5: -129367 | AC5: =SUM(H5:AB5) -> 158911 | AD5: =IFERROR(AC5/F5*100,0)/10000000 -> 0.52970333
A6: P2967 | B6: Aman Aggarwal | C6: ATS1516 | D6: 20_60 | E6: NSEFO | F6: 1 | H6: 0 | I6: 0 | J6: 0 | K6: 0 | L6: 11900 | M6: 0 | N6: -18730 | O6: 0 | P6: 0 | Q6: 0 | R6: 0 | S6: 0 | T6: 0 | U6: 0 | V6: 0 | W6: 0 | X6: 0 | Y6: 0 | Z6: 0 | AA6: 0 | AB6: 0 | AC6: =SUM(H6:AB6) -> -6830 | AD6: =IFERROR(AC6/F6*100,0)/10000000 -> -0.0683
A7: P2990 | B7: Aman Aggarwal | C7: ATS1532 | D7: new strategy_48 | E7: NSEFO | F7: 1 | H7: -63700 | I7: 13000 | J7: 0 | K7: 37000 | L7: 31000 | M7: 0 | N7: 6500 | O7: 28500 | P7: 447 | Q7: 29500 | R7: 23300 | S7: -85900 | T7: 56700 | U7: -13800 | V7: 1560 | W7: 23000 | X7: 27122 | Y7: -38700 | Z7: 0 | AA7: 0 | AB7: -182925 | AC7: =SUM(H7:AB7) -> -107396 | AD7: =IFERROR(AC7/F7*100,0)/10000000 -> -1.07396
A8: P3166 | B8: Aman Dohre | C8: XTS03 | D8: MACD/Direction | E8: STOCK OP | F8: 3 | H8: 179600 | I8: -26565 | J8: -45278 | K8: -46000 | L8: -59835 | M8: 25445 | N8: -46828 | O8: 94220 | P8: -131800 | Q8: 121400 | R8: -30125 | S8: -78630 | T8: 3450 | U8: 81400 | V8: 17000 | W8: 13000 | X8: 65900 | Y8: -123415 | Z8: -196500 | AA8: -21135 | AB8: -157365 | AC8: =SUM(H8:AB8) -> -362061 | AD8: =IFERROR(AC8/F8*100,0)/10000000 -> -1.20687 | AG8: -119642
A9: P3390 | B9: Aman Dohre | C9: XTS34 | D9: NSE FO | E9: NSEFO | F9: 1.5 | H9: 59398 | I9: -14500 | J9: 36650 | K9: -5025 | L9: 18806 | M9: -500 | N9: -34321 | O9: 4630 | P9: 17255 | Q9: 30940 | R9: -63430 | S9: -31200 | T9: -20828 | U9: 32323 | V9: 34000 | W9: -5914 | X9: 18458 | Y9: -12117 | Z9: 11354 | AA9: 0 | AB9: -8756 | AC9: =SUM(H9:AB9) -> 67223 | AD9: =IFERROR(AC9/F9*100,0)/10000000 -> 0.44815333 | AF9: 3588406
A10: P3390_1 | B10: Aman Dohre | C10: ATS1507 | D10: NSE FO | F10: 0.6 | H10: 8234 | I10: -21600 | J10: 21640 | K10: 2000 | L10: 8920 | M10: 2577 | N10: -1822 | O10: 2900 | P10: 8888 | Q10: 9100 | R10: -31500 | S10: -900 | T10: -18262 | U10: 43007 | V10: 19188 | W10: -19806 | X10: 26000 | Y10: 25600 | Z10: 0 | AA10: 0 | AB10: 18156 | AC10: =SUM(H10:AB10) -> 102320 | AD10: =IFERROR(AC10/F10*100,0)/10000000 -> 1.7053333 | AF10: 3468764 | AG10: =(AF10+AF9)/10000000*13780 -> 9724.7803
A11: P3117 | B11: Ansh Aggarwal | C11: ATS_1007 | D11: Falcon | E11: NSEFO | F11: 15 | H11: -413740 | I11: 0 | J11: 0 | K11: 27700 | L11: 59800 | M11: 87600 | N11: 0 | O11: -8276 | P11: -182170 | Q11: -335162 | R11: 0 | S11: 4326 | T11: 0 | U11: 40700 | V11: 56788 | W11: 0 | X11: 0 | Y11: 17500 | Z11: 0 | AA11: 45000 | AB11: 16600 | AC11: =SUM(H11:AB11) -> -583334 | AD11: =IFERROR(AC11/F11*100,0)/10000000 -> -0.38888933
A12: P3323_1 | B12: Amit&Kartik | C12: XTS35 | D12: Strangle/Spread | E12: NSEFO | F12: 6 | H12: -61243 | I12: 50 | J12: -50942 | K12: 0 | L12: 80 | M12: -7456 | N12: 0 | O12: -400 | P12: 50 | Q12: 145167 | R12: -100 | S12: -35135 | T12: 0 | U12: 19322 | V12: 4272 | W12: 0 | X12: -30000 | Y12: 50 | Z12: -4973 | AA12: 8864 | AB12: 0 | AC12: =SUM(H12:AB12) -> -12394 | AD12: =IFERROR(AC12/F12*100,0)/10000000 -> -0.020656667
A13: P2827 | B13: Bharat | C13: UT | D13: ETF | E13: CASH | F13: 1 | H13: -4458 | I13: -2649 | J13: 3000 | K13: 1467 | L13: -2290 | M13: 365 | N13: -161 | O13: 190 | P13: -2915 | Q13: -2745 | R13: 2399 | S13: 0 | T13: 3861 | U13: -1101 | V13: -1410 | W13: 50 | X13: -3513 | Y13: 1746 | Z13: -5989 | AA13: -1061 | AB13: 694 | AC13: =SUM(H13:AB13) -> -14520 | AD13: =IFERROR(AC13/F13*100,0)/10000000 -> -0.1452
A14: P3090 | B14: Bharat | C14: XTS04 | D14: STRADDLE | E14: NSEFO | F14: 2.5 | H14: 724 | I14: 0 | J14: -3828 | K14: 8298 | L14: 3141 | M14: 5219 | N14: 0 | O14: 9114 | P14: 0 | Q14: -8766 | R14: -10140 | S14: -16054 | T14: 10240 | U14: -6096 | V14: -15426 | W14: 6772 | X14: 0 | Y14: 25406 | Z14: -4158 | AA14: -2781 | AB14: -30351 | AC14: =SUM(H14:AB14) -> -28686 | AD14: =IFERROR(AC14/F14*100,0)/10000000 -> -0.114744
A15: P2954 | B15: Yogesh | C15: XTS39 | D15: STRADDLE | E15: NSEFO | F15: 2.2 | H15: -4897 | I15: 0 | J15: -100 | K15: 11194 | L15: 3225 | M15: 3927 | N15: 0 | O15: 8417 | P15: 0 | Q15: -8566 | R15: -6220 | S15: -17616 | T15: 10247 | U15: -3845 | V15: -16614 | W15: 7234 | X15: 0 | Y15: 29112 | Z15: -4184 | AA15: -3146 | AB15: -34983 | AC15: =SUM(H15:AB15) -> -26815 | AD15: =IFERROR(AC15/F15*100,0)/10000000 -> -0.12188636 | AG15: =AG8-AG10 -> -129366.78 | AJ15: 116185 | AL15: =AJ15+AG15 -> -13181.78
A16: P3079 | B16: Yogesh | C16: UT | D16: ETF | E16: CASH | F16: 1 | H16: -11113 | I16: -3245 | J16: 7937 | K16: 5065 | L16: -7918 | M16: 6627 | N16: -4941 | O16: -4200 | P16: 7421 | Q16: -27500 | R16: 5959 | S16: 7570 | T16: 21453 | U16: 250 | V16: -8817 | W16: 9571 | X16: -19300 | Y16: 5254 | Z16: -26788 | AA16: -4990 | AB16: -866 | AC16: =SUM(H16:AB16) -> -42571 | AD16: =IFERROR(AC16/F16*100,0)/10000000 -> -0.42571
A17: P2817 | B17: DK Sir_M | C17: S1504 | D17: Maximum | E17: NSEFO | F17: 2.5 | H17: 0 | I17: 0 | J17: 0 | K17: 0 | L17: 0 | M17: 0 | N17: -32641 | O17: 0 | P17: 0 | Q17: 42220 | R17: 0 | S17: -22321 | T17: 0 | U17: 0 | V17: 24714 | W17: 0 | X17: 72000 | Y17: 0 | Z17: 0 | AA17: 0 | AB17: 0 | AC17: =SUM(H17:AB17) -> 83972 | AD17: =IFERROR(AC17/F17*100,0)/10000000 -> 0.335888 | AL17: 4000000 | AM17: =AL17*7/100 -> 280000 | AO17: =15*12 -> 180
A18: P2792 | B18: DK Sir_T | C18: S1502 | D18: ThanosNF | E18: NSEFO | F18: 4 | H18: 0 | I18: 0 | J18: 0 | K18: 0 | L18: -1657 | M18: 1600 | N18: -48000 | O18: 0 | P18: 0 | Q18: 61600 | R18: 0 | S18: -38652 | T18: 0 | U18: 0 | V18: -60116 | W18: 0 | X18: 26900 | Y18: 0 | Z18: 0 | AA18: 0 | AB18: 0 | AC18: =SUM(H18:AB18) -> -58325 | AD18: =IFERROR(AC18/F18*100,0)/10000000 -> -0.1458125 | AM18: =AM17/12 -> 23333.333
A19: P3311 | B19: Himansu Pal | C19: ATS_1510 | D19: Directional | E19: NSEFO | F19: 1.5 | H19: 17500 | I19: -31966 | J19: 17400 | K19: 7586 | L19: 40075 | M19: -1738 | N19: -62019 | O19: 13500 | P19: -140844 | Q19: 13508 | R19: -73400 | S19: -81145 | T19: 42700 | U19: -9354 | V19: 170513 | W19: 28425 | X19: -22515 | Y19: -72925 | Z19: 48100 | AA19: 0 | AB19: 650 | AC19: =SUM(H19:AB19) -> -95949 | AD19: =IFERROR(AC19/F19*100,0)/10000000 -> -0.63966
A20: P3181 | B20: Harshit | C20: XTS32 | D20: SELF | E20: NSEFO | F20: 1.1 | H20: 9433 | I20: 0 | J20: -11491 | K20: 0 | L20: 1670 | M20: 700 | N20: 10000 | O20: 25655 | P20: -28662 | Q20: -29599 | R20: -52025 | S20: 0 | T20: 0 | U20: 41261 | V20: 19635 | W20: 26807 | X20: -73422 | Y20: 10361 | Z20: -64520 | AA20: 0 | AB20: 84428 | AC20: =SUM(H20:AB20) -> -29769 | AD20: =IFERROR(AC20/F20*100,0)/10000000 -> -0.27062727 | AH20: -132700
A21: P3400 | B21: Aman sharma | C21: XTS37 | D21: SELF | E21: NSEFO | F21: 0.25 | H21: 4737 | I21: -3466 | J21: 2500 | K21: -8570 | L21: 4268 | M21: 6521 | N21: 0 | O21: 20992 | P21: -23384 | Q21: -23681 | R21: 580 | S21: -13500 | T21: 7233 | U21: 18527 | V21: 37130 | W21: -3785 | X21: -4756 | Y21: 3174 | Z21: 0 | AA21: -11007 | AB21: 5260 | AC21: =SUM(H21:AB21) -> 18773 | AD21: =IFERROR(AC21/F21*100,0)/10000000 -> 0.75092 | AH21: -52140
A22: P3091 | B22: Hardik | C22: XTS010 | D22: SELF | E22: NSEFO | F22: 2 | H22: -1048 | I22: 6953 | J22: 2574 | K22: -1344 | L22: -2921 | M22: -3207 | N22: 0 | O22: 0 | P22: 0 | Q22: 0 | R22: 0 | S22: 0 | T22: -714 | U22: -6082 | V22: -201 | W22: -2500 | X22: 801 | Y22: 0 | Z22: 0 | AA22: 0 | AB22: 0 | AC22: =SUM(H22:AB22) -> -7689 | AD22: =IFERROR(AC22/F22*100,0)/10000000 -> -0.038445 | AH22: 0
A23: P3408 | B23: Hardik | C23: XTS20 | D23: SELF | E23: NSEFO | F23: 0.25 | H23: 0 | I23: 0 | J23: 0 | K23: 260 | L23: 80 | M23: 0 | N23: 0 | O23: 0 | P23: 0 | Q23: 0 | R23: 0 | S23: 0 | T23: 0 | U23: 144 | V23: 497 | W23: -900 | X23: -100 | Y23: 0 | Z23: 0 | AA23: 0 | AB23: 0 | AC23: =SUM(H23:AB23) -> -19 | AD23: =IFERROR(AC23/F23*100,0)/10000000 -> -0.00076
